Workbook

Sheet API Token Model
A2: API LLM Token Pricing
A4: Marketplace | B4: Baseline Price | E4: Pricing* | F4: 2026 | G4: 2027 | H4: 2028 | I4: 2029 | J4: 2030
A5: Input Tokens* | B5: 0.1 | E5: Input Tokens | F5: =B5 -> 0.1 | G5: =F5*(1+$B$7) -> 0.105 | H5: =G5*(1+$B$7) -> 0.11025 | I5: =H5*(1+$B$7) -> 0.1157625 | J5: =I5*(1+$B$7) -> 0.12155063
A6: Output Tokens* | B6: 0.4 | E6: Output Tokens | F6: =B6 -> 0.4 | G6: =F6*(1+$B7) -> 0.42 | H6: =G6*(1+$B7) -> 0.441 | I6: =H6*(1+$B7) -> 0.46305 | J6: =I6*(1+$B7) -> 0.4862025
A7: Annual Price Inflation | B7: 0.05 | E7: Average I/O Price | F7: =B5*0.1+B6*0.9 -> 0.37 | G7: =F7*(1+$B$7) -> 0.3885 | H7: =G7*(1+$B$7) -> 0.407925 | I7: =H7*(1+$B$7) -> 0.42832125 | J7: =I7*(1+$B$7) -> 0.44973731
E8: Privacy Service | F8: =F7*(1+B9) -> 0.4625 | G8: =F8*(1+$B$7) -> 0.485625 | H8: =G8*(1+$B$7) -> 0.50990625 | I8: =H8*(1+$B$7) -> 0.53540156 | J8: =I8*(1+$B$7) -> 0.56217164
A9: Privacy Services** | B9: 0.25 | E9: Long Context | F9: =F7*(1+B11) -> 0.4625 | G9: =F9*(1+$B7) -> 0.485625 | H9: =G9*(1+$B7) -> 0.50990625 | I9: =H9*(1+$B7) -> 0.53540156 | J9: =I9*(1+$B7) -> 0.56217164
E10: Privacy + Long Context | F10: =F7*(1+B9+B11) -> 0.555 | G10: =F10*(1+$B7) -> 0.58275 | H10: =G10*(1+$B7) -> 0.6118875 | I10: =H10*(1+$B7) -> 0.64248188 | J10: =I10*(1+$B7) -> 0.67460597
A11: Long Context** | B11: 0.25
E12: Platform Average | F12: =F7*0.75+F8*0.1+F9*0.1+F10*0.05 -> 0.39775 | G12: =G7*0.75+G8*0.1+G9*0.1+G10*0.05 -> 0.4176375 | H12: =H7*0.75+H8*0.1+H9*0.1+H10*0.05 -> 0.43851938 | I12: =I7*0.75+I8*0.1+I9*0.1+I10*0.05 -> 0.46044534 | J12: =J7*0.75+J8*0.1+J9*0.1+J10*0.05 -> 0.48346761
A13: Input/Output Ratio (1:9) | B13: 0.1
A14: Privacy | B14: 0.1
A15: Long Context | B15: 0.1
A16: Privacy + Long Context | B16: 0.05 | E16: Token Demand | F16: 2026 | G16: 2027 | H16: 2028 | I16: 2029 | J16: 2030
A17: Cost Factor (COGS) | B17: 0.2
A18: *Price Per Million Tokens | E18: Low Usage | F18: =$B$23*(1+F20)*12 -> 19440 | G18: =F18*(1+G20) -> 24300 | H18: =G18*(1+H20) -> 31590 | I18: =H18*(1+I20) -> 42646.5 | J18: =I18*(1+J20) -> 59705.1
A19: **Price Premiums | E19: High Usage | F19: =$B24*(1+F20)*12 -> 28800 | G19: =F19*(1+G20) -> 36000 | H19: =G19*(1+H20) -> 46800 | I19: =H19*(1+I20) -> 63180 | J19: =I19*(1+J20) -> 88452
E20: CAGR | F20: =$B$25 -> 0.2 | G20: =F20+$B$26 -> 0.25 | H20: =G20+$B$26 -> 0.3 | I20: =H20+$B$26 -> 0.35 | J20: =I20+$B$26 -> 0.4
A21: Monthly Token Output*** | B21: Baseline
E22: Market Capture
A23: Low Usage | B23: =1.35*10^15/10^12 -> 1350 | C23: Low (Trillions Tokens) | E23: 0.01 | F23: =F18*$E$23 -> 194.4 | G23: =G18*$E$23 -> 243 | H23: =H18*$E$23 -> 315.9 | I23: =I18*$E$23 -> 426.465 | J23: =J18*$E$23 -> 597.051
A24: High Usage | B24: =2*10^15/10^12 -> 2000 | C24: High (Trillions Tokens) | E24: 0.01 | F24: =F19*$E$23 -> 288 | G24: =G19*$E$23 -> 360 | H24: =H19*$E$23 -> 468 | I24: =I19*$E$23 -> 631.8 | J24: =J19*$E$23 -> 884.52
A25: CAGR | B25: 0.2
A26: CAGR Growth | B26: 0.05 | C26: Low (Trillions Tokens) | E26: 0.05 | F26: =F18*$E$26 -> 972 | G26: =G18*$E$26 -> 1215 | H26: =H18*$E$26 -> 1579.5 | I26: =I18*$E$26 -> 2132.325 | J26: =J18*$E$26 -> 2985.255
A27: ***Trillions of Tokens | C27: High (Trillions Tokens) | E27: 0.05 | F27: =F19*$E$27 -> 1440 | G27: =G19*$E$27 -> 1800 | H27: =H19*$E$27 -> 2340 | I27: =I19*$E$27 -> 3159 | J27: =J19*$E$27 -> 4422.6
E29: Annual Revenue @ 1% | F29: =F12*F23*10^6 -> 77322600 | G29: =G12*G23*10^6 -> 1.0148591e+08 | H29: =H12*H23*10^6 -> 1.3852827e+08 | I29: =I12*I23*10^6 -> 1.9636382e+08 | J29: =J12*J23*10^6 -> 2.8865482e+08
E30: Annual Revenue @ 1% | F30: =F12*F24*10^6 -> 1.14552e+08 | G30: =G12*G24*10^6 -> 150349500 | H30: =H12*H24*10^6 -> 2.0522707e+08 | I30: =I12*I24*10^6 -> 2.9090937e+08 | J30: =J12*J24*10^6 -> 4.2763677e+08
C32: Low | E32: Annual Revenue @ 5% | F32: =F26*F12*10^6 -> 3.86613e+08 | G32: =G26*G12*10^6 -> 5.0742956e+08 | H32: =H26*H12*10^6 -> 6.9264135e+08 | I32: =I26*I12*10^6 -> 9.8181912e+08 | J32: =J26*J12*10^6 -> 1.4432741e+09
C33: High | E33: Annual Revenue @ 5% | F33: =F27*F12*10^6 -> 5.7276e+08 | G33: =G27*G12*10^6 -> 751747500 | H33: =H27*H12*10^6 -> 1.0261353e+09 | I33: =I27*I12*10^6 -> 1.4545468e+09 | J33: =J27*J12*10^6 -> 2.1381839e+09
E36: Global Token Demand Growth Monthly (Based on CAGR & CAGR Growth)
E37: 1 | F37: =E37+1 -> 2 | G37: =F37+1 -> 3 | H37: =G37+1 -> 4 | I37: =H37+1 -> 5 | J37: =I37+1 -> 6 | K37: =J37+1 -> 7 | L37: =K37+1 -> 8 | M37: =L37+1 -> 9 | ... BL37: =BK37+1 -> 60
C39: Monthly Growth | E39: =(1+$F$20)^(1/12)-1 -> 0.01530947 | F39: =(1+$F$20)^(1/12)-1 -> 0.01530947 | G39: =(1+$F$20)^(1/12)-1 -> 0.01530947 | H39: =(1+$F$20)^(1/12)-1 -> 0.01530947 | I39: =(1+$F$20)^(1/12)-1 -> 0.01530947 | J39: =(1+$F$20)^(1/12)-1 -> 0.01530947 | K39: =(1+$F$20)^(1/12)-1 -> 0.01530947 | L39: =(1+$F$20)^(1/12)-1 -> 0.01530947 | ... P39: =(1+$F$20)^(1/12)-1 -> 0.01530947 | Q39: =(1+$G$20)^(1/12)-1 -> 0.018769265 | R39: =(1+$G$20)^(1/12)-1 -> 0.018769265 | S39: =(1+$G$20)^(1/12)-1 -> 0.018769265 | T39: =(1+$G$20)^(1/12)-1 -> 0.018769265 | U39: =(1+$G$20)^(1/12)-1 -> 0.018769265 | V39: =(1+$G$20)^(1/12)-1 -> 0.018769265 | W39: =(1+$G$20)^(1/12)-1 -> 0.018769265 | X39: =(1+$G$20)^(1/12)-1 -> 0.018769265 | ... AB39: =(1+$G$20)^(1/12)-1 -> 0.018769265 | AC39: =(1+$H$20)^(1/12)-1 -> 0.022104451 | AD39: =(1+$H$20)^(1/12)-1 -> 0.022104451 | AE39: =(1+$H$20)^(1/12)-1 -> 0.022104451 | AF39: =(1+$H$20)^(1/12)-1 -> 0.022104451 | AG39: =(1+$H$20)^(1/12)-1 -> 0.022104451 | AH39: =(1+$H$20)^(1/12)-1 -> 0.022104451 | AI39: =(1+$H$20)^(1/12)-1 -> 0.022104451 | AJ39: =(1+$H$20)^(1/12)-1 -> 0.022104451 | ... AN39: =(1+$H$20)^(1/12)-1 -> 0.022104451 | AO39: =(1+$I$20)^(1/12)-1 -> 0.025324057 | AP39: =(1+$I$20)^(1/12)-1 -> 0.025324057 | AQ39: =(1+$I$20)^(1/12)-1 -> 0.025324057 | AR39: =(1+$I$20)^(1/12)-1 -> 0.025324057 | AS39: =(1+$I$20)^(1/12)-1 -> 0.025324057 | AT39: =(1+$I$20)^(1/12)-1 -> 0.025324057 | AU39: =(1+$I$20)^(1/12)-1 -> 0.025324057 | AV39: =(1+$I$20)^(1/12)-1 -> 0.025324057 | ... AZ39: =(1+$I$20)^(1/12)-1 -> 0.025324057 | BA39: =(1+$J$20)^(1/12)-1 -> 0.028436156 | BB39: =(1+$J$20)^(1/12)-1 -> 0.028436156 | BC39: =(1+$J$20)^(1/12)-1 -> 0.028436156 | BD39: =(1+$J$20)^(1/12)-1 -> 0.028436156 | BE39: =(1+$J$20)^(1/12)-1 -> 0.028436156 | BF39: =(1+$J$20)^(1/12)-1 -> 0.028436156 | BG39: =(1+$J$20)^(1/12)-1 -> 0.028436156 | BH39: =(1+$J$20)^(1/12)-1 -> 0.028436156 | ... BL39: =(1+$J$20)^(1/12)-1 -> 0.028436156
C40: Low (Trillions Tokens) | E40: =$B$23*(1+E39) -> 1370.6678 | F40: =E40*(1+F39) -> 1391.652 | G40: =F40*(1+G39) -> 1412.9574 | H40: =G40*(1+H39) -> 1434.5891 | I40: =H40*(1+I39) -> 1456.5519 | J40: =I40*(1+J39) -> 1478.8509 | K40: =J40*(1+K39) -> 1501.4913 | L40: =K40*(1+L39) -> 1524.4784 | M40: =L40*(1+M39) -> 1547.8173 | ... BL40: =BK40*(1+BL39) -> 4975.425
C41: High (Trillions Tokens) | E41: =B24*(1+E39) -> 2030.6189 | F41: =E41*(1+F39) -> 2061.7066 | G41: =F41*(1+G39) -> 2093.2703 | H41: =G41*(1+H39) -> 2125.3171 | I41: =H41*(1+I39) -> 2157.8546 | J41: =I41*(1+J39) -> 2190.8902 | K41: =J41*(1+K39) -> 2224.4316 | L41: =K41*(1+L39) -> 2258.4865 | M41: =L41*(1+M39) -> 2293.0627 | ... BL41: =BK41*(1+BL39) -> 7371
A43: Refiant Market Capture
A44: 24 Months S-Curve | E44: 1 | F44: =E44+1 -> 2 | G44: =F44+1 -> 3 | H44: =G44+1 -> 4 | I44: =H44+1 -> 5 | J44: =I44+1 -> 6 | K44: =J44+1 -> 7 | L44: =K44+1 -> 8 | M44: =L44+1 -> 9 | ... AB44: =AA44+1 -> 24 | AC44: 25 | AD44: =AC44+1 -> 26 | AE44: =AD44+1 -> 27 | AF44: =AE44+1 -> 28 | AG44: =AF44+1 -> 29 | AH44: =AG44+1 -> 30 | AI44: =AH44+1 -> 31 | AJ44: =AI44+1 -> 32 | AK44: =AJ44+1 -> 33 | ... BL44: =BK44+1 -> 60
A45: Market Share (End) | B45: 0.01
A46: Endpoint | B46: 24 | C46: Market Share (%) | E46: 0 | F46: 0 | G46: 0 | H46: =$B$45/(1+EXP(-$B$49*(H44-$B$47-$B$48))) -> 4.0701377e-05 | I46: =$B$45/(1+EXP(-$B$49*(I44-$B$47-$B$48))) -> 6.6928509e-05 | J46: =$B$45/(1+EXP(-$B$49*(J44-$B$47-$B$48))) -> 0.00010986943 | K46: =$B$45/(1+EXP(-$B$49*(K44-$B$47-$B$48))) -> 0.0001798621 | L46: =$B$45/(1+EXP(-$B$49*(L44-$B$47-$B$48))) -> 0.00029312231 | M46: =$B$45/(1+EXP(-$B$49*(M44-$B$47-$B$48))) -> 0.00047425873 | N46: =$B$45/(1+EXP(-$B$49*(N44-$B$47-$B$48))) -> 0.0007585818 | O46: =$B$45/(1+EXP(-$B$49*(O44-$B$47-$B$48))) -> 0.0011920292 | ... AB46: =$B$45/(1+EXP(-$B$49*(AB44-$B$47-$B$48))) -> 0.0098901306 | AC46: =AB46*(1+$B$53) -> 0.010129886 | AD46: =AC46*(1+$B$53) -> 0.010375453 | AE46: =AD46*(1+$B$53) -> 0.010626973 | AF46: =AE46*(1+$B$53) -> 0.01088459 | AG46: =AF46*(1+$B$53) -> 0.011148452 | AH46: =AG46*(1+$B$53) -> 0.011418711 | AI46: =AH46*(1+$B$53) -> 0.011695522 | AJ46: =AI46*(1+$B$53) -> 0.011979043 | ... AN46: =AM46*(1+$B$53) -> 0.013183544 | AO46: =AN46*(1+$B$58) -> 0.013503137 | AP46: =AO46*(1+$B$58) -> 0.013830478 | AQ46: =AP46*(1+$B$58) -> 0.014165755 | AR46: =AQ46*(1+$B$58) -> 0.014509158 | AS46: =AR46*(1+$B$58) -> 0.014860887 | AT46: =AS46*(1+$B$58) -> 0.015221142 | AU46: =AT46*(1+$B$58) -> 0.015590131 | AV46: =AU46*(1+$B$58) -> 0.015968064 | ... AZ46: =AY46*(1+$B$58) -> 0.017573664 | BA46: =AZ46*(1+$B$63) -> 0.017903509 | BB46: =BA46*(1+$B$63) -> 0.018239545 | BC46: =BB46*(1+$B$63) -> 0.018581888 | BD46: =BC46*(1+$B$63) -> 0.018930656 | BE46: =BD46*(1+$B$63) -> 0.01928597 | BF46: =BE46*(1+$B$63) -> 0.019647954 | BG46: =BF46*(1+$B$63) -> 0.020016732 | BH46: =BG46*(1+$B$63) -> 0.020392431 | ... BL46: =BK46*(1+$B$63) -> 0.02196708
A47: Midpoint | B47: 12 | C47: Low (Trillions Tokens) | E47: =$F$18*E46 -> 0 | F47: =$F$18*F46 -> 0 | G47: =$F$18*G46 -> 0 | H47: =H46*H40 -> 0.058389751 | I47: =I46*I40 -> 0.097484845 | J47: =J46*J40 -> 0.1624805 | K47: =K46*K40 -> 0.27006138 | L47: =L46*L40 -> 0.44685862 | M47: =M46*M40 -> 0.73406588 | N47: =N46*N40 -> 1.1921216 | O47: =O46*O40 -> 1.9019692 | ... BL47: =BL46*BL40 -> 109.29556
A48: Startpoint | B48: 3 | C48: High (Trillions Tokens) | E48: =$F$19*E46 -> 0 | F48: =$F$19*F46 -> 0 | G48: =$F$19*G46 -> 0 | H48: =H41*H46 -> 0.086503334 | I48: =I41*I46 -> 0.14442199 | J48: =J41*J46 -> 0.24071185 | K48: =K41*K46 -> 0.40009094 | L48: =L41*L46 -> 0.66201277 | M48: =M41*M46 -> 1.087505 | N48: =N41*N46 -> 1.7661061 | O48: =O41*O46 -> 2.8177321 | ... BL48: =BL41*BL46 -> 161.91935
...

Sheet 3 Year Forecast
A1: Details in this file are Under NDA
B2: Variables
A3: Month | C3: 1 | D3: 2 | E3: 3 | F3: 4 | G3: 5 | H3: 6 | I3: 7 | J3: 8 | K3: 9 | L3: 10 | M3: 11 | N3: 12 | O3: =N3+1 -> 13 | P3: =O3+1 -> 14 | Q3: =P3+1 -> 15 | R3: =Q3+1 -> 16 | S3: =R3+1 -> 17 | T3: =S3+1 -> 18 | U3: =T3+1 -> 19 | V3: =U3+1 -> 20 | ... AL3: =AK3+1 -> 36 | AM3: 3 Year Totals
A5: API Token Net Revenue | B5: High | C5: =IF($B$5="Low",'API Token Model'!E59,'API Token Model'!E60 ) -> 0 | D5: =IF($B$5="Low",'API Token Model'!F59,'API Token Model'!F60 ) -> 0 | E5: =IF($B$5="Low",'API Token Model'!G59,'API Token Model'!G60 ) -> 0 | F5: =IF($B$5="Low",'API Token Model'!H59,'API Token Model'!H60 ) -> 27525.361 | G5: =IF($B$5="Low",'API Token Model'!I59,'API Token Model'!I60 ) -> 45955.078 | H5: =IF($B$5="Low",'API Token Model'!J59,'API Token Model'!J60 ) -> 76594.512 | I5: =IF($B$5="Low",'API Token Model'!K59,'API Token Model'!K60 ) -> 127308.94 | J5: =IF($B$5="Low",'API Token Model'!L59,'API Token Model'!L60 ) -> 210652.46 | ... AL5: =IF($B$5="Low",'API Token Model'!AN59,'API Token Model'!AN60 ) -> 17178540 | AM5: =SUM(Q5:AL5) -> 2.4023781e+08
A8: Total Monthly Revenue | C8: =C5 -> 0 | D8: =D5 -> 0 | E8: =E5 -> 0 | F8: =F5 -> 27525.361 | G8: =G5 -> 45955.078 | H8: =H5 -> 76594.512 | I8: =I5 -> 127308.94 | J8: =J5 -> 210652.46 | ... AL8: =AL5 -> 17178540 | AM8: =SUM(C8:AL8) -> 2.4926271e+08
A9: Total Annual Revenue | M9: Year 1 | N9: =SUM(C8:N8) -> 3685805 | S9: 18 Months | T9: =SUM(C8:T8) -> 32403849 | Y9: Year 2 | Z9: =SUM(O8:Z8) -> 83340688 | AK9: Year 3 | AL9: =SUM(AA8:AL8) -> 1.6223622e+08
A11: Cost Structure
A12: Opex Cost (Opex Montly) | C12: =Opex!B45 -> 120500 | D12: =Opex!C45 -> 174500 | E12: =Opex!D45 -> 174500 | F12: =Opex!F45 -> 201000 | G12: =Opex!G45 -> 189500 | H12: =Opex!H45 -> 204500 | I12: =Opex!J45 -> 276000 | J12: =Opex!K45 -> 264500 | K12: =Opex!L45 -> 264500 | L12: =Opex!N45 -> 276000 | M12: =Opex!O45 -> 264500 | N12: =Opex!P45 -> 264500 | O12: =Opex!R45 -> 288000 | P12: =Opex!S45 -> 277225 | Q12: =Opex!T45 -> 277225 | R12: =Opex!U45 -> 288300 | S12: =Opex!V45 -> 277225 | T12: =Opex!W45 -> 277225 | U12: =Opex!Y45 -> 288800 | V12: =Opex!Z45 -> 277725 | W12: =Opex!AA45 -> 277725 | X12: =Opex!AC45 -> 288800 | Y12: =Opex!AD45 -> 277725 | Z12: =Opex!AE45 -> 277725 | AA12: =Opex!AG45 -> 290856.25 | AB12: =Opex!AH45 -> 290856.25 | AC12: =Opex!AI45 -> 290856.25 | AD12: =Opex!AK45 -> 290856.25 | AE12: =Opex!AL45 -> 290856.25 | AF12: =Opex!AM45 -> 290856.25 | AG12: =Opex!AO45 -> 290856.25 | AH12: =Opex!AP45 -> 290856.25 | AI12: =Opex!AQ45 -> 290856.25 | AJ12: =Opex!AS45 -> 288415 | AK12: =Opex!AT45 -> 288415 | AL12: =Opex!AU45 -> 288415 | AM12: =AVERAGE(C12:AL12) -> 264754.2
A14: Net Profit/Loss | C14: =C8-C12 -> -120500 | D14: =D8-D12 -> -174500 | E14: =E8-E12 -> -174500 | F14: =F8-F12 -> -173474.64 | G14: =G8-G12 -> -143544.92 | H14: =H8-H12 -> -127905.49 | I14: =I8-I12 -> -148691.06 | J14: =J8-J12 -> -53847.538 | ... AL14: =AL8-AL12 -> 16890125 | AM14: =SUM(C14:AL14) -> 2.3973156e+08 | AN14: =AM14/AM8 -> 0.96176263
A15: Total Annual Net Profit/Loss | M15: Year 1 | N15: =SUM(C14:N14) -> 1011305 | S15: 18 Months | T15: =SUM(C14:T14) -> 28044149 | Y15: Year 2 | Z15: =SUM(O14:Z14) -> 79966988 | AK15: Year 3 | AL15: =SUM(AA14:AL14) -> 1.5875327e+08
J16: =SUM(C14:J14) -> -1116963.7 | Z16: =Z14/Z5 -> 0.97198425
A17: Capex | E17: =-Capex!E24 -> -399000 | H17: =-Capex!I24 -> -318000 | K17: =-Capex!M24 -> -72000 | N17: =-Capex!Q24 -> -296000
C18: =Capex!B26 -> 293000 | D18: =Capex!C26 -> 53000 | E18: =Capex!D26 -> 53000 | F18: =Capex!F26 -> 53000 | G18: =Capex!G26 -> 53000 | H18: =Capex!H26 -> 53000 | I18: =Capex!J26 -> 8000 | J18: =Capex!K26 -> 8000 | K18: =Capex!L26 -> 8000 | L18: =Capex!N26 -> 8000 | M18: =Capex!N26 -> 8000 | N18: =Capex!O26 -> 8000 | O18: =Capex!P26 -> 8000 | P18: =Capex!S26 -> 8000 | Q18: =Capex!R26 -> 8000 | R18: =Capex!S26 -> 8000 | S18: =Capex!T26 -> 8000 | T18: =Capex!X26 -> 8000 | U18: =Capex!V26 -> 8000 | V18: =Capex!W26 -> 8000 | W18: =Capex!X26 -> 8000 | X18: =Capex!AD26 -> 8000 | Y18: =Capex!Z26 -> 8000 | Z18: =Capex!AA26 -> 8000 | AA18: =Capex!AB26 -> 8000 | AB18: =Capex!AI26 -> 8000 | AC18: =Capex!AD26 -> 8000 | AD18: =Capex!AE26 -> 8000 | AE18: =Capex!AF26 -> 8000 | AF18: =Capex!AN26 -> 8000 | AG18: =Capex!AH26 -> 8000 | AH18: =Capex!AI26 -> 8000 | AI18: =Capex!AJ26 -> 8000 | AJ18: =Capex!AT26 -> 8000 | AK18: =Capex!AL26 -> 8000 | AL18: =Capex!AM26 -> 8000
B19: 4350000 | C19: =B19+C14-C18 -> 3936500 | D19: =C19+D14-D18 -> 3709000 | E19: =D19+E14-E18 -> 3481500 | F19: =E19+F14-F18 -> 3255025.4 | G19: =F19+G14-G18 -> 3058480.4 | H19: =G19+H14-H18 -> 2877575 | I19: =H19+I14-I18 -> 2720883.9 | J19: =I19+J14-J18 -> 2659036.3 | ... U19: =T19+U14-U18 -> 39488004 | V19: =U19+V17+V14 -> 47809241 | W19: =V19+W17+W14 -> 56561397 | X19: =W19+X17+X14 -> 65646892 | Y19: =X19+Y17+Y14 -> 75030843 | Z19: =Y19+Z17+Z14 -> 84666293 | AA19: =Z19+AA17+AA14 -> 94753362 | AB19: =AA19+AB17+AB14 -> 1.0532697e+08 | AC19: =AB19+AC17+AC14 -> 1.1640993e+08 | ... AL19: =AK19+AL17+AL14 -> 2.4341956e+08

Sheet Capex
A1: Cost Category | B1: Q1 | F1: Q2 | J1: Q3 | N1: Q4 | R1: Q5 | V1: Q6 | Z1: Q7 | AD1: Q8 | AH1: Q9 | AL1: Q10 | AP1: Q11 | AT1: Q12
A2: Month | B2: 1 | C2: 2 | D2: 3 | F2: 4 | G2: 5 | H2: 6 | J2: 7 | K2: 8 | L2: 9 | N2: 10 | O2: 11 | P2: 12 | R2: 13 | S2: 14 | T2: 15 | V2: 16 | W2: 17 | X2: 18 | Z2: 19 | AA2: 20 | AB2: 21 | AD2: 22 | AE2: 23 | AF2: 24 | AH2: 25 | AI2: 26 | AJ2: 27 | AL2: 28 | AM2: 29 | AN2: 30 | AP2: 31 | AQ2: 32 | AR2: 33 | AT2: 34 | AU2: 35 | AV2: 36
A3: Legal
A4: Legal & IP
A5: Patent Costs | B5: 25000 | C5: 25000 | D5: 25000 | F5: 25000 | G5: 25000 | H5: 25000 | J5: 0 | K5: 0 | L5: 0 | N5: 0 | O5: 0 | P5: 0 | R5: 0 | S5: 0 | T5: 0 | V5: 0 | W5: 0 | X5: 0 | Z5: 0 | AA5: 0 | AB5: 0 | AD5: 0 | AE5: 0 | AF5: 0 | AH5: 0 | AI5: 0 | AJ5: 0 | AL5: 0 | AM5: 0 | AN5: 0 | AP5: 0 | AQ5: 0 | AR5: 0 | AT5: 0 | AU5: 0 | AV5: 0
A6: Legal Services | B6: 20000 | C6: 20000 | D6: 20000 | F6: 20000 | G6: 20000 | H6: 20000 | J6: 0 | K6: 0 | L6: 0 | N6: 0 | O6: 0 | P6: 0 | R6: 0 | S6: 0 | T6: 0 | V6: 0 | W6: 0 | X6: 0 | Z6: 0 | AA6: 0 | AB6: 0 | AD6: 0 | AE6: 0 | AF6: 0 | AH6: 0 | AI6: 0 | AJ6: 0 | AL6: 0 | AM6: 0 | AN6: 0 | AP6: 0 | AQ6: 0 | AR6: 0 | AT6: 0 | AU6: 0 | AV6: 0
A7: Legal and IP Subtotal | B7: =SUM(B5:B6) -> 45000 | C7: =SUM(C5:C6) -> 45000 | D7: =SUM(D5:D6) -> 45000 | F7: =SUM(F5:F6) -> 45000 | G7: =SUM(G5:G6) -> 45000 | H7: =SUM(H5:H6) -> 45000 | J7: =SUM(J5:J6) -> 0 | K7: =SUM(K5:K6) -> 0 | L7: =SUM(L5:L6) -> 0 | N7: =SUM(N5:N6) -> 0 | O7: =SUM(O5:O6) -> 0 | P7: =SUM(P5:P6) -> 0 | R7: =SUM(R5:R6) -> 0 | S7: =SUM(S5:S6) -> 0 | T7: =SUM(T5:T6) -> 0 | V7: =SUM(V5:V6) -> 0 | W7: =SUM(W5:W6) -> 0 | X7: =SUM(X5:X6) -> 0 | Z7: =SUM(Z5:Z6) -> 0 | AA7: =SUM(AA5:AA6) -> 0 | AB7: =SUM(AB5:AB6) -> 0 | AD7: =SUM(AD5:AD6) -> 0 | AE7: =SUM(AE5:AE6) -> 0 | AF7: =SUM(AF5:AF6) -> 0 | AH7: =SUM(AH5:AH6) -> 0 | AI7: =SUM(AI5:AI6) -> 0 | AJ7: =SUM(AJ5:AJ6) -> 0 | AL7: =SUM(AL5:AL6) -> 0 | AM7: =SUM(AM5:AM6) -> 0 | AN7: =SUM(AN5:AN6) -> 0 | AP7: =SUM(AP5:AP6) -> 0 | AQ7: =SUM(AQ5:AQ6) -> 0 | AR7: =SUM(AR5:AR6) -> 0 | AT7: =SUM(AT5:AT6) -> 0 | AU7: =SUM(AU5:AU6) -> 0 | AV7: =SUM(AV5:AV6) -> 0
A8: IP Subtotal | E8: =SUM(B7:D7) -> 135000 | I8: =SUM(B7:H7) -> 270000 | M8: =SUM(J7:L7) -> 0 | Q8: =SUM(J7:P7) -> 0 | U8: =SUM(R7:T7) -> 0 | Y8: =SUM(R7:X7) -> 0 | AC8: =SUM(V7:AB7) -> 0 | AG8: =SUM(Z7:AF7) -> 0 | AK8: =SUM(AD7:AJ7) -> 0 | AO8: =SUM(AH7:AN7) -> 0 | AS8: =SUM(AL7:AR7) -> 0 | AW8: =SUM(B8:AV8) -> 405000
A10: Cloud
A11: Training/Experiment Budget | B11: 5000 | C11: 5000 | D11: 5000 | F11: 5000 | G11: 5000 | H11: 5000 | J11: 5000 | K11: 5000 | L11: 5000 | N11: 5000 | O11: 5000 | P11: 5000 | R11: 5000 | S11: 5000 | T11: 5000 | V11: 5000 | W11: 5000 | X11: 5000 | Z11: 5000 | AA11: 5000 | AB11: 5000 | AD11: 5000 | AE11: 5000 | AF11: 5000 | AH11: 5000 | AI11: 5000 | AJ11: 5000 | AL11: 5000 | AM11: 5000 | AN11: 5000 | AP11: 5000 | AQ11: 5000 | AR11: 5000 | AT11: 5000 | AU11: 5000 | AV11: 5000
A12: Cloud Subtotal | E12: =SUM(B11:D11) -> 15000 | I12: =SUM(B11:H11) -> 30000 | M12: =SUM(B11:L11) -> 45000 | Q12: =SUM(B11:P11) -> 60000 | U12: =SUM(B11:T11) -> 75000 | Y12: =SUM(B11:X11) -> 90000 | AC12: =SUM(B11:AB11) -> 105000 | AG12: =SUM(B11:AF11) -> 120000 | AK12: =SUM(B11:AJ11) -> 135000 | AO12: =SUM(B11:AN11) -> 150000 | AS12: =SUM(B11:AR11) -> 165000 | AW12: =SUM(B11:AV11) -> 180000
A14: Employee Equipment
A15: Employee Equipment (x10) | B15: 3000 | C15: 3000 | D15: 3000 | F15: 3000 | G15: 3000 | H15: 3000 | J15: 3000 | K15: 3000 | L15: 3000 | N15: 3000 | O15: 3000 | P15: 3000 | R15: 3000 | S15: 3000 | T15: 3000 | V15: 3000 | W15: 3000 | X15: 3000 | Z15: 3000 | AA15: 3000 | AB15: 3000 | AD15: 3000 | AE15: 3000 | AF15: 3000 | AH15: 3000 | AI15: 3000 | AJ15: 3000 | AL15: 3000 | AM15: 3000 | AN15: 3000 | AP15: 3000 | AQ15: 3000 | AR15: 3000 | AT15: 3000 | AU15: 3000 | AV15: 3000
E16: =SUM(B15:D15) -> 9000 | I16: =SUM(B15:H15) -> 18000 | M16: =SUM(B15:L15) -> 27000 | Q16: =SUM(B15:P15) -> 36000 | U16: =SUM(B15:T15) -> 45000 | Y16: =SUM(B15:X15) -> 54000 | AC16: =SUM(B15:AB15) -> 63000 | AG16: =SUM(B15:AF15) -> 72000 | AK16: =SUM(B15:AJ15) -> 81000 | AO16: =SUM(B15:AN15) -> 90000 | AS16: =SUM(B15:AR15) -> 99000 | AW16: =SUM(B15:AV15) -> 108000
A17: Investor Closing | B17: 40000 | C17: 0 | D17: 0 | F17: 0 | G17: 0 | H17: 0 | J17: 0 | K17: 0 | L17: 0 | N17: 0 | O17: 0 | P17: 0 | R17: 0 | S17: 0 | T17: 0 | V17: 0 | W17: 0 | X17: 0 | Z17: 0 | AA17: 0 | AB17: 0 | AD17: 0 | AE17: 0 | AF17: 0 | AH17: 0 | AI17: 0 | AJ17: 0 | AL17: 0 | AM17: 0 | AN17: 0 | AP17: 0 | AQ17: 0 | AR17: 0 | AT17: 0 | AU17: 0 | AV17: 0
E18: =SUM(B17:D17) -> 40000 | I18: =SUM(F17:H17) -> 0 | M18: =SUM(F17:L17) -> 0 | Q18: =SUM(J17:P17) -> 0 | U18: =SUM(R17:T17) -> 0 | Y18: =SUM(R17:X17) -> 0 | AC18: =SUM(V17:AB17) -> 0 | AG18: =SUM(Z17:AF17) -> 0 | AK18: =SUM(AD17:AJ17) -> 0 | AO18: =SUM(AH17:AN17) -> 0 | AS18: =SUM(AL17:AR17) -> 0 | AW18: =SUM(B18:AV18) -> 40000
A19: Other
A20: H1-B Visa | B20: 100000 | C20: 0 | D20: 0 | F20: 0 | G20: 0 | H20: 0 | J20: 0 | K20: 0 | L20: 0 | N20: 0 | O20: 0 | P20: 0 | R20: 0 | S20: 0 | T20: 0 | V20: 0 | W20: 0 | X20: 0 | Z20: 0 | AA20: 0 | AB20: 0 | AD20: 0 | AE20: 0 | AF20: 0 | AH20: 0 | AI20: 0 | AJ20: 0 | AL20: 0 | AM20: 0 | AN20: 0 | AP20: 0 | AQ20: 0 | AR20: 0 | AT20: 0 | AU20: 0 | AV20: 0
A21: H1-B Visa | B21: 100000 | C21: 0 | D21: 0 | F21: 0 | G21: 0 | H21: 0 | J21: 0 | K21: 0 | L21: 0 | N21: 0 | O21: 0 | P21: 0 | R21: 0 | S21: 0 | T21: 0 | V21: 0 | W21: 0 | X21: 0 | Z21: 0 | AA21: 0 | AB21: 0 | AD21: 0 | AE21: 0 | AF21: 0 | AH21: 0 | AI21: 0 | AJ21: 0 | AL21: 0 | AM21: 0 | AN21: 0 | AP21: 0 | AQ21: 0 | AR21: 0 | AT21: 0 | AU21: 0 | AV21: 0
A22: other subtotal | B22: =SUM(B20:B21) -> 200000 | C22: =SUM(C20:C21) -> 0 | D22: =SUM(D20:D21) -> 0 | F22: =SUM(F20:F21) -> 0 | G22: =SUM(G20:G21) -> 0 | H22: =SUM(H20:H21) -> 0 | J22: =SUM(J20:J21) -> 0 | K22: =SUM(K20:K21) -> 0 | L22: =SUM(L20:L21) -> 0 | N22: =SUM(N20:N21) -> 0 | O22: =SUM(O20:O21) -> 0 | P22: =SUM(P20:P21) -> 0 | R22: =SUM(R20:R21) -> 0 | S22: =SUM(S20:S21) -> 0 | T22: =SUM(T20:T21) -> 0 | V22: =SUM(V20:V21) -> 0 | W22: =SUM(W20:W21) -> 0 | X22: =SUM(X20:X21) -> 0 | Z22: =SUM(Z20:Z21) -> 0 | AA22: =SUM(AA20:AA21) -> 0 | AB22: =SUM(AB20:AB21) -> 0 | AD22: =SUM(AD20:AD21) -> 0 | AE22: =SUM(AE20:AE21) -> 0 | AF22: =SUM(AF20:AF21) -> 0 | AH22: =SUM(AH20:AH21) -> 0 | AI22: =SUM(AI20:AI21) -> 0 | AJ22: =SUM(AJ20:AJ21) -> 0 | AL22: =SUM(AL20:AL21) -> 0 | AM22: =SUM(AM20:AM21) -> 0 | AN22: =SUM(AN20:AN21) -> 0 | AP22: =SUM(AP20:AP21) -> 0 | AQ22: =SUM(AQ20:AQ21) -> 0 | AR22: =SUM(AR20:AR21) -> 0 | AT22: =SUM(AT20:AT21) -> 0 | AU22: =SUM(AU20:AU21) -> 0 | AV22: =SUM(AV20:AV21) -> 0
E23: =SUM(B22:D22) -> 200000 | I23: =SUM(F22:H22) -> 0 | M23: =SUM(F22:L22) -> 0 | Q23: =SUM(B22:P22) -> 200000 | U23: =SUM(R22:T22) -> 0 | Y23: =SUM(R22:X22) -> 0 | AC23: =SUM(V22:AB22) -> 0 | AG23: =SUM(Z22:AF22) -> 0 | AK23: =SUM(AD22:AJ22) -> 0 | AO23: =SUM(AH22:AN22) -> 0 | AS23: =SUM(AL22:AR22) -> 0 | AW23: =SUM(B22:AV22) -> 200000
A24: Total: | E24: =SUM(E3:E23) -> 399000 | I24: =SUM(I5:I23) -> 318000 | M24: =SUM(M5:M23) -> 72000 | Q24: =SUM(Q23+Q12+Q16) -> 296000 | U24: =SUM(U3:U23) -> 120000 | Y24: =SUM(Y5:Y23) -> 144000 | AC24: =SUM(AC5:AC23) -> 168000 | AG24: =SUM(AG5:AG23) -> 192000 | AK24: =SUM(AK5:AK23) -> 216000 | AO24: =SUM(AO5:AO23) -> 240000 | AS24: =SUM(AS5:AS23) -> 264000 | AW24: =SUM(AW5:AW23) -> 933000
B26: =B22+B17+B15+B11+B7 -> 293000 | C26: =C22+C17+C15+C11+C7 -> 53000 | D26: =D22+D17+D15+D11+D7 -> 53000 | F26: =F22+F17+F15+F11+F7 -> 53000 | G26: =G22+G17+G15+G11+G7 -> 53000 | H26: =H22+H17+H15+H11+H7 -> 53000 | J26: =J22+J17+J15+J11+J7 -> 8000 | K26: =K22+K17+K15+K11+K7 -> 8000 | L26: =L22+L17+L15+L11+L7 -> 8000 | N26: =N22+N17+N15+N11+N7 -> 8000 | O26: =O22+O17+O15+O11+O7 -> 8000 | P26: =P22+P17+P15+P11+P7 -> 8000 | R26: =R22+R17+R15+R11+R7 -> 8000 | S26: =S22+S17+S15+S11+S7 -> 8000 | T26: =T22+T17+T15+T11+T7 -> 8000 | V26: =V22+V17+V15+V11+V7 -> 8000 | W26: =W22+W17+W15+W11+W7 -> 8000 | X26: =X22+X17+X15+X11+X7 -> 8000 | Z26: =Z22+Z17+Z15+Z11+Z7 -> 8000 | AA26: =AA22+AA17+AA15+AA11+AA7 -> 8000 | AB26: =AB22+AB17+AB15+AB11+AB7 -> 8000 | AD26: =AD22+AD17+AD15+AD11+AD7 -> 8000 | AE26: =AE22+AE17+AE15+AE11+AE7 -> 8000 | AF26: =AF22+AF17+AF15+AF11+AF7 -> 8000 | AH26: =AH22+AH17+AH15+AH11+AH7 -> 8000 | AI26: =AI22+AI17+AI15+AI11+AI7 -> 8000 | AJ26: =AJ22+AJ17+AJ15+AJ11+AJ7 -> 8000 | AL26: =AL22+AL17+AL15+AL11+AL7 -> 8000 | AM26: =AM22+AM17+AM15+AM11+AM7 -> 8000 | AN26: =AN22+AN17+AN15+AN11+AN7 -> 8000 | AP26: =AP22+AP17+AP15+AP11+AP7 -> 8000 | AQ26: =AQ22+AQ17+AQ15+AQ11+AQ7 -> 8000 | AR26: =AR22+AR17+AR15+AR11+AR7 -> 8000 | AT26: =AT22+AT17+AT15+AT11+AT7 -> 8000 | AU26: =AU22+AU17+AU15+AU11+AU7 -> 8000 | AV26: =AV22+AV17+AV15+AV11+AV7 -> 8000
E27: =SUM(B26:D26) -> 399000 | I27: =SUM(F26:H26) -> 159000 | M27: =SUM(J26:L26) -> 24000 | Q27: =SUM(N26:P26) -> 24000 | U27: =SUM(R26:T26) -> 24000 | Y27: =SUM(V26:X26) -> 24000 | AC27: =SUM(Z26:AB26) -> 24000 | AG27: =SUM(AD26:AF26) -> 24000 | AK27: =SUM(AH26:AJ26) -> 24000 | AO27: =SUM(AL26:AN26) -> 24000 | AS27: =SUM(AP26:AR26) -> 24000 | AW27: =SUM(AT26:AV26) -> 24000
AW28: =SUM(B27:AW27) -> 798000

Sheet Opex
A1: Cost Category | B1: Q1 | F1: Q2 | J1: Q3 | N1: Q4 | R1: Q5 | U1: Q6 | Y1: Q7 | AC1: Q8 | AG1: Q9 | AK1: Q10 | AO1: Q11 | AS1: Q12
B2: 1 | C2: 2 | D2: 3 | F2: 4 | G2: 5 | H2: 6 | J2: 7 | K2: 8 | L2: 9 | N2: 10 | O2: 11 | P2: 12 | R2: 13 | S2: 14 | T2: 15 | U2: 16 | V2: 17 | W2: 18 | Y2: 19 | Z2: 20 | AA2: 21 | AC2: 22 | AD2: 23 | AE2: 24 | AG2: 25 | AH2: 26 | AI2: 27 | AK2: 28 | AL2: 29 | AM2: 30 | AO2: 31 | AP2: 32 | AQ2: 33 | AS2: 34 | AT2: 35 | AU2: 36
A3: Personal and Services
A4: CEO | B4: =250000/12 -> 20833.333 | C4: =250000/12 -> 20833.333 | D4: =250000/12 -> 20833.333 | F4: =250000/12 -> 20833.333 | G4: =250000/12 -> 20833.333 | H4: =250000/12 -> 20833.333 | J4: =250000/12 -> 20833.333 | K4: =250000/12 -> 20833.333 | L4: =250000/12 -> 20833.333 | N4: =250000/12 -> 20833.333 | O4: =250000/12 -> 20833.333 | P4: =250000/12 -> 20833.333 | R4: =250000/12+(250000/12)*(5%) -> 21875 | S4: =250000/12+(250000/12)*(5%) -> 21875 | T4: =250000/12+(250000/12)*(5%) -> 21875 | U4: =250000/12+(250000/12)*(5%) -> 21875 | V4: =250000/12+(250000/12)*(5%) -> 21875 | W4: =250000/12+(250000/12)*(5%) -> 21875 | Y4: =250000/12+(250000/12)*(5%) -> 21875 | Z4: =250000/12+(250000/12)*(5%) -> 21875 | AA4: =250000/12+(250000/12)*(5%) -> 21875 | AC4: =250000/12+(250000/12)*(5%) -> 21875 | AD4: =250000/12+(250000/12)*(5%) -> 21875 | AE4: =250000/12+(250000/12)*(5%) -> 21875 | AG4: =21875+21875*5% -> 22968.75 | AH4: =21875+21875*5% -> 22968.75 | AI4: =21875+21875*5% -> 22968.75 | AK4: =21875+21875*5% -> 22968.75 | AL4: =21875+21875*5% -> 22968.75 | AM4: =21875+21875*5% -> 22968.75 | AO4: =21875+21875*5% -> 22968.75 | AP4: =21875+21875*5% -> 22968.75 | AQ4: =21875+21875*5% -> 22968.75 | AS4: =21875+21875*5% -> 22968.75 | AT4: =21875+21875*5% -> 22968.75 | AU4: =21875+21875*5% -> 22968.75
A5: CTO | B5: =250000/12 -> 20833.333 | C5: =250000/12 -> 20833.333 | D5: =250000/12 -> 20833.333 | F5: =250000/12 -> 20833.333 | G5: =250000/12 -> 20833.333 | H5: =250000/12 -> 20833.333 | J5: =250000/12 -> 20833.333 | K5: =250000/12 -> 20833.333 | L5: =250000/12 -> 20833.333 | N5: =250000/12 -> 20833.333 | O5: =250000/12 -> 20833.333 | P5: =250000/12 -> 20833.333 | R5: =250000/12+(250000/12)*(5%) -> 21875 | S5: =250000/12+(250000/12)*(5%) -> 21875 | T5: =250000/12+(250000/12)*(5%) -> 21875 | U5: =250000/12+(250000/12)*(5%) -> 21875 | V5: =250000/12+(250000/12)*(5%) -> 21875 | W5: =250000/12+(250000/12)*(5%) -> 21875 | Y5: =250000/12+(250000/12)*(5%) -> 21875 | Z5: =250000/12+(250000/12)*(5%) -> 21875 | AA5: =250000/12+(250000/12)*(5%) -> 21875 | AC5: =250000/12+(250000/12)*(5%) -> 21875 | AD5: =250000/12+(250000/12)*(5%) -> 21875 | AE5: =250000/12+(250000/12)*(5%) -> 21875 | AG5: =21875+21875*5% -> 22968.75 | AH5: =21875+21875*5% -> 22968.75 | AI5: =21875+21875*5% -> 22968.75 | AK5: =21875+21875*5% -> 22968.75 | AL5: =21875+21875*5% -> 22968.75 | AM5: =21875+21875*5% -> 22968.75 | AO5: =21875+21875*5% -> 22968.75 | AP5: =21875+21875*5% -> 22968.75 | AQ5: =21875+21875*5% -> 22968.75 | AS5: =21875+21875*5% -> 22968.75 | AT5: =21875+21875*5% -> 22968.75 | AU5: =21875+21875*5% -> 22968.75
A6: CPO/COO | B6: =250000/12 -> 20833.333 | C6: =250000/12 -> 20833.333 | D6: =250000/12 -> 20833.333 | F6: =250000/12 -> 20833.333 | G6: =250000/12 -> 20833.333 | H6: =250000/12 -> 20833.333 | J6: =250000/12 -> 20833.333 | K6: =250000/12 -> 20833.333 | L6: =250000/12 -> 20833.333 | N6: =250000/12 -> 20833.333 | O6: =250000/12 -> 20833.333 | P6: =250000/12 -> 20833.333 | R6: =250000/12+(250000/12)*(5%) -> 21875 | S6: =250000/12+(250000/12)*(5%) -> 21875 | T6: =250000/12+(250000/12)*(5%) -> 21875 | U6: =250000/12+(250000/12)*(5%) -> 21875 | V6: =250000/12+(250000/12)*(5%) -> 21875 | W6: =250000/12+(250000/12)*(5%) -> 21875 | Y6: =250000/12+(250000/12)*(5%) -> 21875 | Z6: =250000/12+(250000/12)*(5%) -> 21875 | AA6: =250000/12+(250000/12)*(5%) -> 21875 | AC6: =250000/12+(250000/12)*(5%) -> 21875 | AD6: =250000/12+(250000/12)*(5%) -> 21875 | AE6: =250000/12+(250000/12)*(5%) -> 21875 | AG6: =21875+21875*5% -> 22968.75 | AH6: =21875+21875*5% -> 22968.75 | AI6: =21875+21875*5% -> 22968.75 | AK6: =21875+21875*5% -> 22968.75 | AL6: =21875+21875*5% -> 22968.75 | AM6: =21875+21875*5% -> 22968.75 | AO6: =21875+21875*5% -> 22968.75 | AP6: =21875+21875*5% -> 22968.75 | AQ6: =21875+21875*5% -> 22968.75 | AS6: =21875+21875*5% -> 22968.75 | AT6: =21875+21875*5% -> 22968.75 | AU6: =21875+21875*5% -> 22968.75
A7: CFO (fractional first 6 months) | B7: 5000 | C7: 5000 | D7: 5000 | F7: 5000 | G7: 5000 | H7: 5000 | J7: 15000 | K7: 15000 | L7: 15000 | N7: 15000 | O7: 15000 | P7: 15000 | R7: =15000+15000*5% -> 15750 | S7: =15000+15000*5% -> 15750 | T7: =15000+15000*5% -> 15750 | U7: =15000+15000*5% -> 15750 | V7: =15000+15000*5% -> 15750 | W7: =15000+15000*5% -> 15750 | Y7: =15000+15000*5% -> 15750 | Z7: =15000+15000*5% -> 15750 | AA7: =15000+15000*5% -> 15750 | AC7: =15000+15000*5% -> 15750 | AD7: =15000+15000*5% -> 15750 | AE7: =15000+15000*5% -> 15750 | AG7: =15750+15750*5% -> 16537.5 | AH7: =15750+15750*5% -> 16537.5 | AI7: =15750+15750*5% -> 16537.5 | AK7: =15750+15750*5% -> 16537.5 | AL7: =15750+15750*5% -> 16537.5 | AM7: =15750+15750*5% -> 16537.5 | AO7: =15750+15750*5% -> 16537.5 | AP7: =15750+15750*5% -> 16537.5 | AQ7: =15750+15750*5% -> 16537.5 | AS7: =15750+15750*5% -> 16537.5 | AT7: =15750+15750*5% -> 16537.5 | AU7: =15750+15750*5% -> 16537.5
A8: AI Research Engineer #1 | B8: 0 | C8: 15000 | D8: 15000 | F8: 15000 | G8: 15000 | H8: 15000 | J8: 15000 | K8: 15000 | L8: 15000 | N8: 15000 | O8: 15000 | P8: 15000 | R8: =15000+15000*5% -> 15750 | S8: =15000+15000*5% -> 15750 | T8: =15000+15000*5% -> 15750 | U8: =15000+15000*5% -> 15750 | V8: =15000+15000*5% -> 15750 | W8: =15000+15000*5% -> 15750 | Y8: =15000+15000*5% -> 15750 | Z8: =15000+15000*5% -> 15750 | AA8: =15000+15000*5% -> 15750 | AC8: =15000+15000*5% -> 15750 | AD8: =15000+15000*5% -> 15750 | AE8: =15000+15000*5% -> 15750 | AG8: =15750+15750*5% -> 16537.5 | AH8: =15750+15750*5% -> 16537.5 | AI8: =15750+15750*5% -> 16537.5 | AK8: =15750+15750*5% -> 16537.5 | AL8: =15750+15750*5% -> 16537.5 | AM8: =15750+15750*5% -> 16537.5 | AO8: =15750+15750*5% -> 16537.5 | AP8: =15750+15750*5% -> 16537.5 | AQ8: =15750+15750*5% -> 16537.5 | AS8: =15750+15750*5% -> 16537.5 | AT8: =15750+15750*5% -> 16537.5 | AU8: =15750+15750*5% -> 16537.5
A9: AI Research Engineer #2 | B9: 0 | C9: 15000 | D9: 15000 | F9: 15000 | G9: 15000 | H9: 15000 | J9: 15000 | K9: 15000 | L9: 15000 | N9: 15000 | O9: 15000 | P9: 15000 | R9: =15000+15000*5% -> 15750 | S9: =15000+15000*5% -> 15750 | T9: =15000+15000*5% -> 15750 | U9: =15000+15000*5% -> 15750 | V9: =15000+15000*5% -> 15750 | W9: =15000+15000*5% -> 15750 | Y9: =15000+15000*5% -> 15750 | Z9: =15000+15000*5% -> 15750 | AA9: =15000+15000*5% -> 15750 | AC9: =15000+15000*5% -> 15750 | AD9: =15000+15000*5% -> 15750 | AE9: =15000+15000*5% -> 15750 | AG9: =15750+15750*5% -> 16537.5 | AH9: =15750+15750*5% -> 16537.5 | AI9: =15750+15750*5% -> 16537.5 | AK9: =15750+15750*5% -> 16537.5 | AL9: =15750+15750*5% -> 16537.5 | AM9: =15750+15750*5% -> 16537.5 | AO9: =15750+15750*5% -> 16537.5 | AP9: =15750+15750*5% -> 16537.5 | AQ9: =15750+15750*5% -> 16537.5 | AS9: =15750+15750*5% -> 16537.5 | AT9: =15750+15750*5% -> 16537.5 | AU9: =15750+15750*5% -> 16537.5
A10: Product Engineer #1 | B10: 0 | C10: 10000 | D10: 10000 | F10: 10000 | G10: 10000 | H10: 10000 | J10: 10000 | K10: 10000 | L10: 10000 | N10: 10000 | O10: 10000 | P10: 10000 | R10: =10000+10000*5% -> 10500 | S10: =10000+10000*5% -> 10500 | T10: =10000+10000*5% -> 10500 | U10: =10000+10000*5% -> 10500 | V10: =10000+10000*5% -> 10500 | W10: =10000+10000*5% -> 10500 | Y10: =10000+10000*5% -> 10500 | Z10: =10000+10000*5% -> 10500 | AA10: =10000+10000*5% -> 10500 | AC10: =10000+10000*5% -> 10500 | AD10: =10000+10000*5% -> 10500 | AE10: =10000+10000*5% -> 10500 | AG10: =10500+10500*5% -> 11025 | AH10: =10500+10500*5% -> 11025 | AI10: =10500+10500*5% -> 11025 | AK10: =10500+10500*5% -> 11025 | AL10: =10500+10500*5% -> 11025 | AM10: =10500+10500*5% -> 11025 | AO10: =10500+10500*5% -> 11025 | AP10: =10500+10500*5% -> 11025 | AQ10: =10500+10500*5% -> 11025 | AS10: =10500+10500*5% -> 11025 | AT10: =10500+10500*5% -> 11025 | AU10: =10500+10500*5% -> 11025
A11: Product Engineer #2 | B11: 0 | C11: 10000 | D11: 10000 | F11: 10000 | G11: 10000 | H11: 10000 | J11: 10000 | K11: 10000 | L11: 10000 | N11: 10000 | O11: 10000 | P11: 10000 | R11: =10000+10000*5% -> 10500 | S11: =10000+10000*5% -> 10500 | T11: =10000+10000*5% -> 10500 | U11: =10000+10000*5% -> 10500 | V11: =10000+10000*5% -> 10500 | W11: =10000+10000*5% -> 10500 | Y11: =10000+10000*5% -> 10500 | Z11: =10000+10000*5% -> 10500 | AA11: =10000+10000*5% -> 10500 | AC11: =10000+10000*5% -> 10500 | AD11: =10000+10000*5% -> 10500 | AE11: =10000+10000*5% -> 10500 | AG11: =10500+10500*5% -> 11025 | AH11: =10500+10500*5% -> 11025 | AI11: =10500+10500*5% -> 11025 | AK11: =10500+10500*5% -> 11025 | AL11: =10500+10500*5% -> 11025 | AM11: =10500+10500*5% -> 11025 | AO11: =10500+10500*5% -> 11025 | AP11: =10500+10500*5% -> 11025 | AQ11: =10500+10500*5% -> 11025 | AS11: =10500+10500*5% -> 11025 | AT11: =10500+10500*5% -> 11025 | AU11: =10500+10500*5% -> 11025
A12: UX/UI Frontend Developer | B12: 0 | C12: 10000 | D12: 10000 | F12: 10000 | G12: 10000 | H12: 10000 | J12: 10000 | K12: 10000 | L12: 10000 | N12: 10000 | O12: 10000 | P12: 10000 | R12: =10000+10000*5% -> 10500 | S12: =10000+10000*5% -> 10500 | T12: =10000+10000*5% -> 10500 | U12: =10000+10000*5% -> 10500 | V12: =10000+10000*5% -> 10500 | W12: =10000+10000*5% -> 10500 | Y12: =10000+10000*5% -> 10500 | Z12: =10000+10000*5% -> 10500 | AA12: =10000+10000*5% -> 10500 | AC12: =10000+10000*5% -> 10500 | AD12: =10000+10000*5% -> 10500 | AE12: =10000+10000*5% -> 10500 | AG12: =10500+10500*5% -> 11025 | AH12: =10500+10500*5% -> 11025 | AI12: =10500+10500*5% -> 11025 | AK12: =10500+10500*5% -> 11025 | AL12: =10500+10500*5% -> 11025 | AM12: =10500+10500*5% -> 11025 | AO12: =10500+10500*5% -> 11025 | AP12: =10500+10500*5% -> 11025 | AQ12: =10500+10500*5% -> 11025 | AS12: =10500+10500*5% -> 11025 | AT12: =10500+10500*5% -> 11025 | AU12: =10500+10500*5% -> 11025
A13: DevOPs Team | B13: 0 | C13: 0 | D13: 0 | F13: 0 | G13: 0 | H13: 15000 | J13: 15000 | K13: 15000 | L13: 15000 | N13: 15000 | O13: 15000 | P13: 15000 | R13: =15000+15000*5% -> 15750 | S13: =15000+15000*5% -> 15750 | T13: =15000+15000*5% -> 15750 | U13: =15000+15000*5% -> 15750 | V13: =15000+15000*5% -> 15750 | W13: =15000+15000*5% -> 15750 | Y13: =15000+15000*5% -> 15750 | Z13: =15000+15000*5% -> 15750 | AA13: =15000+15000*5% -> 15750 | AC13: =15000+15000*5% -> 15750 | AD13: =15000+15000*5% -> 15750 | AE13: =15000+15000*5% -> 15750 | AG13: =15750+15750*5% -> 16537.5 | AH13: =15750+15750*5% -> 16537.5 | AI13: =15750+15750*5% -> 16537.5 | AK13: =15750+15750*5% -> 16537.5 | AL13: =15750+15750*5% -> 16537.5 | AM13: =15750+15750*5% -> 16537.5 | AO13: =15750+15750*5% -> 16537.5 | AP13: =15750+15750*5% -> 16537.5 | AQ13: =15750+15750*5% -> 16537.5 | AS13: =15750+15750*5% -> 16537.5 | AT13: =15750+15750*5% -> 16537.5 | AU13: =15750+15750*5% -> 16537.5
A14: HR Services | B14: 1500 | C14: 1500 | D14: 1500 | F14: 1500 | G14: 1500 | H14: 1500 | J14: 6500 | K14: 6500 | L14: 6500 | N14: 6500 | O14: 6500 | P14: 6500 | R14: =6500+6500*5% -> 6825 | S14: =6500+6500*5% -> 6825 | T14: =6500+6500*5% -> 6825 | U14: =6500+6500*5% -> 6825 | V14: =6500+6500*5% -> 6825 | W14: =6500+6500*5% -> 6825 | Y14: =6500+6500*5% -> 6825 | Z14: =6500+6500*5% -> 6825 | AA14: =6500+6500*5% -> 6825 | AC14: =6500+6500*5% -> 6825 | AD14: =6500+6500*5% -> 6825 | AE14: =6500+6500*5% -> 6825 | AG14: =6825+6825*5% -> 7166.25 | AH14: =6825+6825*5% -> 7166.25 | AI14: =6825+6825*5% -> 7166.25 | AK14: =6825+6825*5% -> 7166.25 | AL14: =6825+6825*5% -> 7166.25 | AM14: =6825+6825*5% -> 7166.25 | AO14: =6825+6825*5% -> 7166.25 | AP14: =6825+6825*5% -> 7166.25 | AQ14: =6825+6825*5% -> 7166.25 | AS14: =4500+4500*5% -> 4725 | AT14: =4500+4500*5% -> 4725 | AU14: =4500+4500*5% -> 4725
A15: GC Services | B15: 3000 | C15: 3000 | D15: 3000 | F15: 3000 | G15: 3000 | H15: 3000 | J15: 3000 | K15: 3000 | L15: 3000 | N15: 3000 | O15: 3000 | P15: 3000 | R15: 3000 | S15: =3000+3000*5% -> 3150 | T15: =3000+3000*5% -> 3150 | U15: =3000+3000*5% -> 3150 | V15: =3000+3000*5% -> 3150 | W15: =3000+3000*5% -> 3150 | Y15: =3000+3000*5% -> 3150 | Z15: =3000+3000*5% -> 3150 | AA15: =3000+3000*5% -> 3150 | AC15: =3000+3000*5% -> 3150 | AD15: =3000+3000*5% -> 3150 | AE15: =3000+3000*5% -> 3150 | AG15: =3150+3150*5% -> 3307.5 | AH15: =3150+3150*5% -> 3307.5 | AI15: =3150+3150*5% -> 3307.5 | AK15: =3150+3150*5% -> 3307.5 | AL15: =3150+3150*5% -> 3307.5 | AM15: =3150+3150*5% -> 3307.5 | AO15: =3150+3150*5% -> 3307.5 | AP15: =3150+3150*5% -> 3307.5 | AQ15: =3150+3150*5% -> 3307.5 | AS15: =3150+3150*5% -> 3307.5 | AT15: =3150+3150*5% -> 3307.5 | AU15: =3150+3150*5% -> 3307.5
A16: Accounting Services | B16: 3000 | C16: 3000 | D16: 3000 | F16: 3000 | G16: 3000 | H16: 3000 | J16: 3000 | K16: 3000 | L16: 3000 | N16: 3000 | O16: 3000 | P16: 3000 | R16: 3000 | S16: =3000+3000*5% -> 3150 | T16: =3000+3000*5% -> 3150 | U16: =3000+3000*5% -> 3150 | V16: =3000+3000*5% -> 3150 | W16: =3000+3000*5% -> 3150 | Y16: =3000+3000*5% -> 3150 | Z16: =3000+3000*5% -> 3150 | AA16: =3000+3000*5% -> 3150 | AC16: =3000+3000*5% -> 3150 | AD16: =3000+3000*5% -> 3150 | AE16: =3000+3000*5% -> 3150 | AG16: =3150+3150*5% -> 3307.5 | AH16: =3150+3150*5% -> 3307.5 | AI16: =3150+3150*5% -> 3307.5 | AK16: =3150+3150*5% -> 3307.5 | AL16: =3150+3150*5% -> 3307.5 | AM16: =3150+3150*5% -> 3307.5 | AO16: =3150+3150*5% -> 3307.5 | AP16: =3150+3150*5% -> 3307.5 | AQ16: =3150+3150*5% -> 3307.5 | AS16: =3150+3150*5% -> 3307.5 | AT16: =3150+3150*5% -> 3307.5 | AU16: =3150+3150*5% -> 3307.5
A17: Customer Success (Sales) #1 | B17: 0 | C17: 5500 | D17: 5500 | F17: 5500 | G17: 5500 | H17: 5500 | J17: 5500 | K17: 5500 | L17: 5500 | N17: 5500 | O17: 5500 | P17: 5500 | R17: =5500+5500*5% -> 5775 | S17: =5500+5500*5% -> 5775 | T17: =5500+5500*5% -> 5775 | U17: =5500+5500*5% -> 5775 | V17: =5500+5500*5% -> 5775 | W17: =5500+5500*5% -> 5775 | Y17: =5500+5500*5% -> 5775 | Z17: =5500+5500*5% -> 5775 | AA17: =5500+5500*5% -> 5775 | AC17: =5500+5500*5% -> 5775 | AD17: =5500+5500*5% -> 5775 | AE17: =5500+5500*5% -> 5775 | AG17: =5775+5775*5% -> 6063.75 | AH17: =5775+5775*5% -> 6063.75 | AI17: =5775+5775*5% -> 6063.75 | AK17: =5775+5775*5% -> 6063.75 | AL17: =5775+5775*5% -> 6063.75 | AM17: =5775+5775*5% -> 6063.75 | AO17: =5775+5775*5% -> 6063.75 | AP17: =5775+5775*5% -> 6063.75 | AQ17: =5775+5775*5% -> 6063.75 | AS17: =5775+5775*5% -> 6063.75 | AT17: =5775+5775*5% -> 6063.75 | AU17: =5775+5775*5% -> 6063.75
A18: Customer Success (Sales) #2 | B18: 0 | C18: 0 | D18: 0 | F18: 0 | G18: 0 | H18: 0 | J18: 5500 | K18: 5500 | L18: 5500 | N18: 5500 | O18: 5500 | P18: 5500 | R18: =5500+5500*5% -> 5775 | S18: =5500+5500*5% -> 5775 | T18: =5500+5500*5% -> 5775 | U18: =5500+5500*5% -> 5775 | V18: =5500+5500*5% -> 5775 | W18: =5500+5500*5% -> 5775 | Y18: =5500+5500*5% -> 5775 | Z18: =5500+5500*5% -> 5775 | AA18: =5500+5500*5% -> 5775 | AC18: =5500+5500*5% -> 5775 | AD18: =5500+5500*5% -> 5775 | AE18: =5500+5500*5% -> 5775 | AG18: =5775+5775*5% -> 6063.75 | AH18: =5775+5775*5% -> 6063.75 | AI18: =5775+5775*5% -> 6063.75 | AK18: =5775+5775*5% -> 6063.75 | AL18: =5775+5775*5% -> 6063.75 | AM18: =5775+5775*5% -> 6063.75 | AO18: =5775+5775*5% -> 6063.75 | AP18: =5775+5775*5% -> 6063.75 | AQ18: =5775+5775*5% -> 6063.75 | AS18: =5775+5775*5% -> 6063.75 | AT18: =5775+5775*5% -> 6063.75 | AU18: =5775+5775*5% -> 6063.75
A19: Personal and Services Subtotal | B19: =SUM(B3:B17) -> 75000 | C19: =SUM(C3:C17) -> 140500 | D19: =SUM(D3:D17) -> 140500 | F19: =SUM(F3:F17) -> 140500 | G19: =SUM(G3:G17) -> 140500 | H19: =SUM(H3:H17) -> 155500 | J19: =SUM(J3:J17) -> 170500 | K19: =SUM(K3:K17) -> 170500 | L19: =SUM(L3:L17) -> 170500 | N19: =SUM(N3:N17) -> 170500 | O19: =SUM(O3:O17) -> 170500 | P19: =SUM(P3:P17) -> 170500 | R19: =SUM(R3:R17) -> 178725 | S19: =SUM(S3:S17) -> 179025 | T19: =SUM(T3:T17) -> 179025 | U19: =SUM(U3:U17) -> 179025 | V19: =SUM(V3:V17) -> 179025 | W19: =SUM(W3:W17) -> 179025 | Y19: =SUM(Y3:Y17) -> 179025 | Z19: =SUM(Z3:Z17) -> 179025 | AA19: =SUM(AA3:AA17) -> 179025 | AC19: =SUM(AC3:AC17) -> 179025 | AD19: =SUM(AD3:AD17) -> 179025 | AE19: =SUM(AE3:AE17) -> 179025 | AG19: =SUM(AG3:AG17) -> 187976.25 | AH19: =SUM(AH3:AH17) -> 187976.25 | AI19: =SUM(AI3:AI17) -> 187976.25 | AK19: =SUM(AK3:AK17) -> 187976.25 | AL19: =SUM(AL3:AL17) -> 187976.25 | AM19: =SUM(AM3:AM17) -> 187976.25 | AO19: =SUM(AO3:AO17) -> 187976.25 | AP19: =SUM(AP3:AP17) -> 187976.25 | AQ19: =SUM(AQ3:AQ17) -> 187976.25 | AS19: =SUM(AS3:AS17) -> 185535 | AT19: =SUM(AT3:AT17) -> 185535 | AU19: =SUM(AU3:AU17) -> 185535
E20: =SUM(B19:D19) -> 356000 | I20: =SUM(B19:H19) -> 792500 | M20: =SUM(B19:L19) -> 1304000 | Q20: =SUM(B19:P19) -> 1815500 | X20: =SUM(B19:W19) -> 2889350 | AB20: =SUM(B19:AA19) -> 3426425 | AF20: =SUM(B19:AE19) -> 3963500 | AJ20: =SUM(B19:AI19) -> 4527428.8 | AN20: =SUM(B19:AM19) -> 5091357.5 | AR20: =SUM(B19:AQ19) -> 5655286.2 | AV20: =SUM(B19:AU19) -> 6211891.2
A21: Legal & IP
A22: Patent Costs | B22: 0 | C22: 0 | D22: 0 | F22: 0 | G22: 0 | H22: 0 | J22: 5000 | K22: 5000 | L22: 5000 | N22: 5000 | O22: 5000 | P22: 5000 | R22: 5000 | S22: 5000 | T22: 5000 | U22: 5000 | V22: 5000 | W22: 5000 | Y22: =5000+(5000)*5% -> 5250 | Z22: =5000+(5000)*5% -> 5250 | AA22: =5000+(5000)*5% -> 5250 | AC22: =5000+(5000)*5% -> 5250 | AD22: =5000+(5000)*5% -> 5250 | AE22: =5000+(5000)*5% -> 5250 | AG22: =5000+(5000)*5% -> 5250 | AH22: =5000+(5000)*5% -> 5250 | AI22: =5000+(5000)*5% -> 5250 | AK22: =5000+(5000)*5% -> 5250 | AL22: =5000+(5000)*5% -> 5250 | AM22: =5000+(5000)*5% -> 5250 | AO22: =5000+(5000)*5% -> 5250 | AP22: =5000+(5000)*5% -> 5250 | AQ22: =5000+(5000)*5% -> 5250 | AS22: =5000+(5000)*5% -> 5250 | AT22: =5000+(5000)*5% -> 5250 | AU22: =5000+(5000)*5% -> 5250
A23: Legal Services | B23: 0 | C23: 0 | D23: 0 | F23: 0 | G23: 0 | H23: 0 | J23: 5000 | K23: 5000 | L23: 5000 | N23: 5000 | O23: 5000 | P23: 5000 | R23: 5000 | S23: 5000 | T23: 5000 | U23: 5000 | V23: 5000 | W23: 5000 | Y23: =5000+(5000)*5% -> 5250 | Z23: =5000+(5000)*5% -> 5250 | AA23: =5000+(5000)*5% -> 5250 | AC23: =5000+(5000)*5% -> 5250 | AD23: =5000+(5000)*5% -> 5250 | AE23: =5000+(5000)*5% -> 5250 | AG23: =5000+(5000)*5% -> 5250 | AH23: =5000+(5000)*5% -> 5250 | AI23: =5000+(5000)*5% -> 5250 | AK23: =5000+(5000)*5% -> 5250 | AL23: =5000+(5000)*5% -> 5250 | AM23: =5000+(5000)*5% -> 5250 | AO23: =5000+(5000)*5% -> 5250 | AP23: =5000+(5000)*5% -> 5250 | AQ23: =5000+(5000)*5% -> 5250 | AS23: =5000+(5000)*5% -> 5250 | AT23: =5000+(5000)*5% -> 5250 | AU23: =5000+(5000)*5% -> 5250
A24: Legal and IP Subtotal | B24: 0 | C24: 0 | D24: 0 | F24: 0 | G24: 0 | H24: 0 | J24: =SUM(J22:J23) -> 10000 | K24: =SUM(K22:K23) -> 10000 | L24: =SUM(L22:L23) -> 10000 | N24: =SUM(N22:N23) -> 10000 | O24: =SUM(O22:O23) -> 10000 | P24: =SUM(P22:P23) -> 10000 | R24: =SUM(R22:R23) -> 10000 | S24: =SUM(S22:S23) -> 10000 | T24: =SUM(T22:T23) -> 10000 | U24: =SUM(U22:U23) -> 10000 | V24: =SUM(V22:V23) -> 10000 | W24: =SUM(W22:W23) -> 10000 | Y24: =SUM(Y22:Y23) -> 10500 | Z24: =SUM(Z22:Z23) -> 10500 | AA24: =SUM(AA22:AA23) -> 10500 | AC24: =SUM(AC22:AC23) -> 10500 | AD24: =SUM(AD22:AD23) -> 10500 | AE24: =SUM(AE22:AE23) -> 10500 | AG24: =SUM(AG22:AG23) -> 10500 | AH24: =SUM(AH22:AH23) -> 10500 | AI24: =SUM(AI22:AI23) -> 10500 | AK24: =SUM(AK22:AK23) -> 10500 | AL24: =SUM(AL22:AL23) -> 10500 | AM24: =SUM(AM22:AM23) -> 10500 | AO24: =SUM(AO22:AO23) -> 10500 | AP24: =SUM(AP22:AP23) -> 10500 | AQ24: =SUM(AQ22:AQ23) -> 10500 | AS24: =SUM(AS22:AS23) -> 10500 | AT24: =SUM(AT22:AT23) -> 10500 | AU24: =SUM(AU22:AU23) -> 10500
E25: =SUM(B24:D24) -> 0 | I25: =SUM(B24:H24) -> 0 | M25: =SUM(B24:L24) -> 30000 | Q25: =SUM(B24:P24) -> 60000 | X25: =SUM(B24:W24) -> 120000 | AB25: =SUM(B24:AA24) -> 151500 | AF25: =SUM(B24:AE24) -> 183000 | AJ25: =SUM(B24:AI24) -> 214500 | AN25: =SUM(B24:AM24) -> 246000 | AR25: =SUM(B24:AQ24) -> 277500 | AV25: =SUM(B24:AU24) -> 309000
A26: Sales and Marketing
A27: Agency Fees | B27: 15000 | C27: 15000 | D27: 15000 | F27: 15000 | G27: 15000 | H27: 15000 | J27: 15000 | K27: 15000 | L27: 15000 | N27: 15000 | O27: 15000 | P27: 15000 | R27: =15000+15000*5% -> 15750 | S27: =15000+15000*5% -> 15750 | T27: =15000+15000*5% -> 15750 | U27: =15000+15000*5% -> 15750 | V27: =15000+15000*5% -> 15750 | W27: =15000+15000*5% -> 15750 | Y27: =15000+15000*5% -> 15750 | Z27: =15000+15000*5% -> 15750 | AA27: =15000+15000*5% -> 15750 | AC27: =15000+15000*5% -> 15750 | AD27: =15000+15000*5% -> 15750 | AE27: =15000+15000*5% -> 15750 | AG27: =15750+15750*5% -> 16537.5 | AH27: =15750+15750*5% -> 16537.5 | AI27: =15750+15750*5% -> 16537.5 | AK27: =15750+15750*5% -> 16537.5 | AL27: =15750+15750*5% -> 16537.5 | AM27: =15750+15750*5% -> 16537.5 | AO27: =15750+15750*5% -> 16537.5 | AP27: =15750+15750*5% -> 16537.5 | AQ27: =15750+15750*5% -> 16537.5 | AS27: =15750+15750*5% -> 16537.5 | AT27: =15750+15750*5% -> 16537.5 | AU27: =15750+15750*5% -> 16537.5
A28: Advertising | B28: 0 | C28: 0 | D28: 0 | F28: 15000 | G28: 15000 | H28: 15000 | J28: 50000 | K28: 50000 | L28: 50000 | N28: 50000 | O28: 50000 | P28: 50000 | R28: =50000+50000*5% -> 52500 | S28: =50000+50000*5% -> 52500 | T28: =50000+50000*5% -> 52500 | U28: =50000+50000*5% -> 52500 | V28: =50000+50000*5% -> 52500 | W28: =50000+50000*5% -> 52500 | Y28: =50000+50000*5% -> 52500 | Z28: =50000+50000*5% -> 52500 | AA28: =50000+50000*5% -> 52500 | AC28: =50000+50000*5% -> 52500 | AD28: =50000+50000*5% -> 52500 | AE28: =50000+50000*5% -> 52500 | AG28: =52500+50000*5% -> 55000 | AH28: =52500+50000*5% -> 55000 | AI28: =52500+50000*5% -> 55000 | AK28: =52500+50000*5% -> 55000 | AL28: =52500+50000*5% -> 55000 | AM28: =52500+50000*5% -> 55000 | AO28: =52500+50000*5% -> 55000 | AP28: =52500+50000*5% -> 55000 | AQ28: =52500+50000*5% -> 55000 | AS28: =52500+50000*5% -> 55000 | AT28: =52500+50000*5% -> 55000 | AU28: =52500+50000*5% -> 55000
A29: Sales and Marketing Subtotal | B29: =SUM(B27:B28) -> 15000 | C29: =SUM(C27:C28) -> 15000 | D29: =SUM(D27:D28) -> 15000 | F29: =SUM(F27:F28) -> 30000 | G29: =SUM(G27:G28) -> 30000 | H29: =SUM(H27:H28) -> 30000 | J29: =SUM(J27:J28) -> 65000 | K29: =SUM(K27:K28) -> 65000 | L29: =SUM(L27:L28) -> 65000 | N29: =SUM(N27:N28) -> 65000 | O29: =SUM(O27:O28) -> 65000 | P29: =SUM(P27:P28) -> 65000 | R29: =SUM(R27:R28) -> 68250 | S29: =SUM(S27:S28) -> 68250 | T29: =SUM(T27:T28) -> 68250 | U29: =SUM(U27:U28) -> 68250 | V29: =SUM(V27:V28) -> 68250 | W29: =SUM(W27:W28) -> 68250 | Y29: =SUM(Y27:Y28) -> 68250 | Z29: =SUM(Z27:Z28) -> 68250 | AA29: =SUM(AA27:AA28) -> 68250 | AC29: =SUM(AC27:AC28) -> 68250 | AD29: =SUM(AD27:AD28) -> 68250 | AE29: =SUM(AE27:AE28) -> 68250 | AG29: =SUM(AG27:AG28) -> 71537.5 | AH29: =SUM(AH27:AH28) -> 71537.5 | AI29: =SUM(AI27:AI28) -> 71537.5 | AK29: =SUM(AK27:AK28) -> 71537.5 | AL29: =SUM(AL27:AL28) -> 71537.5 | AM29: =SUM(AM27:AM28) -> 71537.5 | AO29: =SUM(AO27:AO28) -> 71537.5 | AP29: =SUM(AP27:AP28) -> 71537.5 | AQ29: =SUM(AQ27:AQ28) -> 71537.5 | AS29: =SUM(AS27:AS28) -> 71537.5 | AT29: =SUM(AT27:AT28) -> 71537.5 | AU29: =SUM(AU27:AU28) -> 71537.5
E30: =SUM(B29:D29) -> 45000 | I30: =SUM(B29:H29) -> 135000 | M30: =SUM(B29:L29) -> 330000 | Q30: =SUM(B29:P29) -> 525000 | X30: =SUM(B29:W29) -> 934500 | AB30: =SUM(B29:AA29) -> 1139250 | AF30: =SUM(B29:AE29) -> 1344000 | AJ30: =SUM(B29:AI29) -> 1558612.5 | AN30: =SUM(B29:AM29) -> 1773225 | AR30: =SUM(B29:AQ29) -> 1987837.5 | AV30: =SUM(B29:AU29) -> 2202450
A31: Travel Expenses
A32: Travel & Accommodation | B32: 20000 | C32: 8500 | D32: 8500 | F32: 20000 | G32: 8500 | H32: 8500 | J32: 20000 | K32: 8500 | L32: 8500 | N32: 20000 | O32: 8500 | P32: 8500 | R32: 20000 | S32: =8500+8500*5% -> 8925 | T32: =8500+8500*5% -> 8925 | U32: 20000 | V32: =8500+8500*5% -> 8925 | W32: =8500+8500*5% -> 8925 | Y32: 20000 | Z32: =8500+8500*5% -> 8925 | AA32: =8500+8500*5% -> 8925 | AC32: 20000 | AD32: =8500+8500*5% -> 8925 | AE32: =8500+8500*5% -> 8925 | AG32: =8925+8925*5% -> 9371.25 | AH32: =8925+8925*5% -> 9371.25 | AI32: =8925+8925*5% -> 9371.25 | AK32: =8925+8925*5% -> 9371.25 | AL32: =8925+8925*5% -> 9371.25 | AM32: =8925+8925*5% -> 9371.25 | AO32: =8925+8925*5% -> 9371.25 | AP32: =8925+8925*5% -> 9371.25 | AQ32: =8925+8925*5% -> 9371.25 | AS32: =8925+8925*5% -> 9371.25 | AT32: =8925+8925*5% -> 9371.25 | AU32: =8925+8925*5% -> 9371.25
A33: Travel and Expenses Subtotal | B33: =SUM(B32) -> 20000 | C33: =SUM(C32) -> 8500 | D33: =SUM(D32) -> 8500 | F33: =SUM(F32) -> 20000 | G33: =SUM(G32) -> 8500 | H33: =SUM(H32) -> 8500 | J33: =SUM(J32) -> 20000 | K33: =SUM(K32) -> 8500 | L33: =SUM(L32) -> 8500 | N33: =SUM(N32) -> 20000 | O33: =SUM(O32) -> 8500 | P33: =SUM(P32) -> 8500 | R33: =SUM(R32) -> 20000 | S33: =SUM(S32) -> 8925 | T33: =SUM(T32) -> 8925 | U33: =SUM(U32) -> 20000 | V33: =SUM(V32) -> 8925 | W33: =SUM(W32) -> 8925 | Y33: =SUM(Y32) -> 20000 | Z33: =SUM(Z32) -> 8925 | AA33: =SUM(AA32) -> 8925 | AC33: =SUM(AC32) -> 20000 | AD33: =SUM(AD32) -> 8925 | AE33: =SUM(AE32) -> 8925 | AG33: =SUM(AG32) -> 9371.25 | AH33: =SUM(AH32) -> 9371.25 | AI33: =SUM(AI32) -> 9371.25 | AK33: =SUM(AK32) -> 9371.25 | AL33: =SUM(AL32) -> 9371.25 | AM33: =SUM(AM32) -> 9371.25 | AO33: =SUM(AO32) -> 9371.25 | AP33: =SUM(AP32) -> 9371.25 | AQ33: =SUM(AQ32) -> 9371.25 | AS33: =SUM(AS32) -> 9371.25 | AT33: =SUM(AT32) -> 9371.25 | AU33: =SUM(AU32) -> 9371.25
E34: =SUM(B32:D32) -> 37000 | I34: =SUM(B32:H32) -> 74000 | M34: =SUM(B32:L32) -> 111000 | Q34: =SUM(B32:P32) -> 148000 | X34: =SUM(B32:W32) -> 223700 | AB34: =SUM(B32:AA32) -> 261550 | AF34: =SUM(B32:AE32) -> 299400 | AV34: =SUM(B32:AD32) -> 290475
A35: Infrastructure
A36: Hosting and Storage | B36: 10000 | C36: 10000 | D36: 10000 | F36: 10000 | G36: 10000 | H36: 10000 | J36: =10000+10000*10% -> 11000 | K36: =10000+10000*10% -> 11000 | L36: =10000+10000*10% -> 11000 | N36: =11000+11000*20% -> 13200 | O36: =11000+11000*20% -> 13200 | P36: =11000+11000*20% -> 13200 | R36: =13200+13200*30% -> 17160 | S36: =13200+13200*30% -> 17160 | T36: =13200+13200*30% -> 17160 | U36: =17160+17160*40% -> 24024 | V36: =17160+17160*40% -> 24024 | W36: =17160+17160*40% -> 24024 | Y36: =24024+24024*60% -> 38438.4 | Z36: =24024+24024*60% -> 38438.4 | AA36: =24024+24024*60% -> 38438.4 | AC36: =38438+38438*100% -> 76876 | AD36: =38438+38438*100% -> 76876 | AE36: =38438+38438*100% -> 76876 | AG36: =38438+38438*100% -> 76876 | AH36: =38438+38438*100% -> 76876 | AI36: =38438+38438*100% -> 76876 | AK36: =76876+76876*30% -> 99938.8 | AL36: =76876+76876*30% -> 99938.8 | AM36: =76876+76876*30% -> 99938.8 | AO36: =99938+99938*20% -> 119925.6 | AP36: =99938+99938*20% -> 119925.6 | AQ36: =99938+99938*20% -> 119925.6 | AS36: =119925+119925*10% -> 131917.5 | AT36: =119925+119925*10% -> 131917.5 | AU36: =119925+119925*10% -> 131917.5
A37: Infrastructure Subtotal | B37: =SUM(B36) -> 10000 | C37: =SUM(C36) -> 10000 | D37: =SUM(D36) -> 10000 | F37: 10000 | G37: 10000 | H37: 10000 | J37: =10000+10000*10% -> 11000 | K37: =10000+10000*10% -> 11000 | L37: =10000+10000*10% -> 11000 | N37: =11000+11000*20% -> 13200 | O37: =11000+11000*20% -> 13200 | P37: =11000+11000*20% -> 13200 | R37: =13200+13200*30% -> 17160 | S37: =13200+13200*30% -> 17160 | T37: =13200+13200*30% -> 17160 | U37: =17160+17160*40% -> 24024 | V37: =17160+17160*40% -> 24024 | W37: =17160+17160*40% -> 24024 | Y37: =24024+24024*60% -> 38438.4 | Z37: =24024+24024*60% -> 38438.4 | AA37: =24024+24024*60% -> 38438.4 | AC37: =38438+38438*100% -> 76876 | AD37: =38438+38438*100% -> 76876 | AE37: =38438+38438*100% -> 76876 | AG37: =38438+38438*100% -> 76876 | AH37: =38438+38438*100% -> 76876 | AI37: =38438+38438*100% -> 76876 | AK37: =76876+76876*30% -> 99938.8 | AL37: =76876+76876*30% -> 99938.8 | AM37: =76876+76876*30% -> 99938.8 | AO37: =99938+99938*20% -> 119925.6 | AP37: =99938+99938*20% -> 119925.6 | AQ37: =99938+99938*20% -> 119925.6 | AS37: =119925+119925*10% -> 131917.5 | AT37: =119925+119925*10% -> 131917.5 | AU37: =119925+119925*10% -> 131917.5
E38: =SUM(B37:D37) -> 30000 | I38: =SUM(B37:H37) -> 60000 | M38: =SUM(B37:L37) -> 93000 | Q38: =SUM(B37:P37) -> 132600 | X38: =SUM(B37:W37) -> 256152 | AB38: =SUM(B37:AA37) -> 371467.2 | AF38: =SUM(B37:AE37) -> 602095.2 | AJ38: =SUM(B37:AI37) -> 832723.2 | AN38: =SUM(B37:AM37) -> 1132539.6 | AR38: =SUM(B37:AQ37) -> 1492316.4 | AV38: =SUM(B37:AU37) -> 1888068.9
A39: Other
A40: Rent | B40: 8500 | C40: 8500 | D40: 8500 | F40: 8500 | G40: 8500 | H40: 8500 | J40: 8500 | K40: 8500 | L40: 8500 | N40: 8500 | O40: 8500 | P40: 8500 | R40: =8500+8500*5% -> 8925 | S40: =8500+8500*5% -> 8925 | T40: =8500+8500*5% -> 8925 | U40: =8500+8500*5% -> 8925 | V40: =8500+8500*5% -> 8925 | W40: =8500+8500*5% -> 8925 | Y40: =8500+8500*5% -> 8925 | Z40: =8500+8500*5% -> 8925 | AA40: =8500+8500*5% -> 8925 | AC40: =8500+8500*5% -> 8925 | AD40: =8500+8500*5% -> 8925 | AE40: =8500+8500*5% -> 8925 | AG40: =8925+8925*5% -> 9371.25 | AH40: =8925+8925*5% -> 9371.25 | AI40: =8925+8925*5% -> 9371.25 | AK40: =8925+8925*5% -> 9371.25 | AL40: =8925+8925*5% -> 9371.25 | AM40: =8925+8925*5% -> 9371.25 | AO40: =8925+8925*5% -> 9371.25 | AP40: =8925+8925*5% -> 9371.25 | AQ40: =8925+8925*5% -> 9371.25 | AS40: =8925+8925*5% -> 9371.25 | AT40: =8925+8925*5% -> 9371.25 | AU40: =8925+8925*5% -> 9371.25
...
