Workbook
Name _Growth_M_Data: 'ST Forecast (M)'!$N$11:$AQ$67
Name _Growth_M_Data: '[1]Growth Rnd Forecast (M)'!$I$8:$AT$76
Name _Growth_M_Labels: 'ST Forecast (M)'!$C$11:$C$67
Name _Growth_M_Labels: '[1]Growth Rnd Forecast (M)'!$C$8:$C$76
Name _Growth_M_MonthEnd: 'ST Forecast (M)'!$N$5:$AQ$5
Name _Growth_M_QuarterEnd: 'ST Forecast (M)'!#REF!
Name _Growth_M_QuarterEnd: '[1]Growth Rnd Forecast (M)'!$I$3:$AT$3
Name _Growth_M_YearEnd: 'ST Forecast (M)'!$N$7:$AQ$7
Name _GrowthSource2_M_Data: '[1]Cost Forecast (v2)'!$F$9:$AQ$55
Name _GrowthSource2_M_Labels: '[1]Cost Forecast (v2)'!$D$9:$D$55
Name _GrowthSource2_M_MonthEnd: '[1]Cost Forecast (v2)'!$F$3:$AQ$3
Name _Hist_M_Data: '[1]Hist PnL (M)'!$H$11:$V$123
Name _Hist_M_Data: 'Historical PnL (M)'!$H$12:$AE$129
Name _Hist_M_Labels: '[1]Hist PnL (M)'!$C$11:$C$123
Name _Hist_M_Labels: 'Historical PnL (M)'!$C$12:$C$129
Name _Hist_M_MonthEnd: 'Historical PnL (M)'!$H$5:$AE$5
Name _Hist_M_QuarterEnd: '[1]Hist PnL (M)'!$H$3:$V$3
Name _Hist_M_YearEnd: 'Historical PnL (M)'!$H$7:$AE$7
Name _HistBS_M_Data: 'Historical BS'!$E$9:$AB$102
Name _HistBS_M_Labels: 'Historical BS'!$C$9:$C$102
Name _HistBS_M_MonthEnd: 'Historical BS'!$E$5:$AB$5
Name _HistCFS_M_Data: '[1]Historical CFS'!$D$9:$R$41
Name _HistCFS_M_Data: 'Historical CFS'!$D$9:$AA$102
Name _HistCFS_M_Labels: '[1]Historical CFS'!$C$9:$C$41
Name _HistCFS_M_Labels: 'Historical CFS'!$C$9:$C$102
Name _HistCFS_M_MonthEnd: '[1]Historical CFS'!$D$5:$R$5
Name _HistCFS_M_MonthEnd: 'Historical CFS'!$D$5:$AA$5
Name _HistIS_M_Data: '[1]Historical IS'!$D$8:$R$123
Name _HistIS_M_Data: 'Historical IS'!$E$8:$AC$145
Name _HistIS_M_Labels: '[1]Historical IS'!$C$8:$C$123
Name _HistIS_M_Labels: 'Historical IS'!$C$8:$C$145
Name _HistIS_M_MonthEnd: '[1]Historical IS'!$D$5:$R$5
Name _HistIS_M_MonthEnd: 'Historical IS'!$E$5:$AC$5
Name _STForecast_M_Data: 'ST Forecast (M)'!$H$12:$AQ$65
Name _STForecast_M_Labels: 'ST Forecast (M)'!$C$12:$C$65
Name _STForecast_M_MonthEnd: 'ST Forecast (M)'!$H$5:$AQ$5
Name _STForecast_M_YearEnd: 'ST Forecast (M)'!$H$7:$AQ$7

Sheet Cover
C5: XGS Enterprise Model
C9: Version: | D9: =MID(CELL("filename"),SEARCH("[",CELL("filename"))+1,SEARCH("]",CELL("filename"))-SEARCH("[",CELL("filename"))-6) -> 5.10 XGS Enterprise Model_Confidential_2026.02.17
C10: Date: | D10: =TODAY() -> 46071
C22: CONFIDENTIAL

Sheet Intro
B2: XGS Enterprise Model
B3: Intro
B5: Description
B6: This is a dynamic multi-year model that integrates historical performance data from the previous fiscal year with forward-looking projections across two time horizons. The model provides detailed three-year forecasts incorporating operational assumptions, alongside strategic ten-year projections to capture the full growth trajectory.
B9: Sheet | C9: Type | D9: Description | E9: Time Range
B10: =HYPERLINK($A$1, "Intro") -> Intro | C10: Index | D10: Model navigation index and links
B11: =HYPERLINK("#Inputs!$A$1", "Inputs") -> Inputs | C11: Inputs | D11: Key drivers and assumptions for the model, primarily around long-term forecasts
B12: =HYPERLINK("#'Consolidated Forecast (A)'!A1", "Consolidated Forecast (A)") -> Consolidated Forecast (A) | C12: Summary Financials | D12: Annual consolidated enterprise model incorporating historical financials, short term forecasts, and long term forecasts | E12: 2024-2035
B13: =HYPERLINK("#'ST Forecast (M)'!A1", "ST Forecast (M)") -> ST Forecast (M) | C13: Financials | D13: Monthly short term expense forecasts focused on uses of growth round proceeds | E13: 2025Q2-2028
B14: =HYPERLINK("#'Historical PnL (M)'!A1", "Historical PnL (M)") -> Historical PnL (M) | C14: Financials | D14: Monthly historical PnL | E14: 2024-2025
B15: =HYPERLINK("#'Historical IS'!A1", "Historical IS") -> Historical IS | C15: Historical Financials | D15: Monthly audited Income Statements | E15: 2024-2025
B16: =HYPERLINK("#'Historical BS'!A1", "Historical BS") -> Historical BS | C16: Historical Financials | D16: Monthly audited Balance Sheets | E16: 2024-2025
B17: =HYPERLINK("#'Historical CFS'!A1", "Historical CFS") -> Historical CFS | C17: Historical Financials | D17: Monthly audited Cash Flow Statements | E17: 2024-2025

Sheet Consolidated Model >

Sheet Inputs
B2: XGS Enterprise Model
B3: Inputs & Assumptions
B5: Time Period
C7: Model Month Start | F7: 45322
C8: Model Month End | F8: 49674
B10: Project Phasing by Geography
C12: MW Deployed By Geography | F12: 2027 | G12: =F12+1 -> 2028 | H12: =G12+1 -> 2029 | I12: =H12+1 -> 2030 | J12: =I12+1 -> 2031 | K12: =J12+1 -> 2032 | L12: =K12+1 -> 2033 | M12: =L12+1 -> 2034 | N12: =M12+1 -> 2035 | P12: 2030 TOTAL | Q12: 2035 TOTAL
D13: SoCal (Imperial + Coso) | E13: MW | F13: 0 | G13: 50 | H13: 400 | I13: 200 | J13: 300 | K13: 300 | L13: 0 | M13: 0 | N13: 0 | P13: =SUM(F13:I13) -> 650 | Q13: =SUM(F13:N13) -> 1250
D14: NorCal (Geysers) | E14: MW | F14: 0 | G14: 150 | H14: 500 | I14: 1000 | J14: 1500 | K14: 1000 | L14: 0 | M14: 0 | N14: 0 | P14: =SUM(F14:I14) -> 1650 | Q14: =SUM(F14:N14) -> 4150
D15: New Mexico | E15: MW | F15: 30 | G15: 150 | H15: 250 | I15: 400 | J15: 720 | K15: 1000 | L15: 0 | M15: 0 | N15: 0 | P15: =SUM(F15:I15) -> 830 | Q15: =SUM(F15:N15) -> 2550
D16: Oregon | E16: MW | F16: 0 | G16: 0 | H16: 0 | I16: 50 | J16: 200 | K16: 1750 | L16: 1500 | M16: 0 | N16: 0 | P16: =SUM(F16:I16) -> 50 | Q16: =SUM(F16:N16) -> 3500
D17: US West | E17: MW | F17: 0 | G17: 0 | H17: 0 | I17: 0 | J17: 0 | K17: 0 | L17: 500 | M17: 2000 | N17: 2500 | P17: =SUM(F17:I17) -> 0 | Q17: =SUM(F17:N17) -> 5000
D18: Philippines | E18: MW | F18: 0 | G18: 0 | H18: 0 | I18: 0 | J18: 0 | K18: 500 | L18: 0 | M18: 0 | N18: 0 | P18: =SUM(F18:I18) -> 0 | Q18: =SUM(F18:N18) -> 500
D19: APAC (Indonesia, NZ , Taiwan) | E19: MW | F19: 0 | G19: 0 | H19: 0 | I19: 0 | J19: 0 | K19: 0 | L19: 500 | M19: 500 | N19: 500 | P19: =SUM(F19:I19) -> 0 | Q19: =SUM(F19:N19) -> 1500
D20: Saudi Arabia | E20: MW | F20: 0 | G20: 0 | H20: 0 | I20: 0 | J20: 0 | K20: 0 | L20: 1000 | M20: 2000 | N20: 2500 | P20: =SUM(F20:I20) -> 0 | Q20: =SUM(F20:N20) -> 5500
D21: Japan | E21: MW | F21: 0 | G21: 0 | H21: 0 | I21: 0 | J21: 0 | K21: 0 | L21: 1500 | M21: 2500 | N21: 3000 | P21: =SUM(F21:I21) -> 0 | Q21: =SUM(F21:N21) -> 7000
D22: All Geographies | E22: MW | F22: =SUM(F13:F21) -> 30 | G22: =SUM(G13:G21) -> 350 | H22: =SUM(H13:H21) -> 1150 | I22: =SUM(I13:I21) -> 1650 | J22: =SUM(J13:J21) -> 2720 | K22: =SUM(K13:K21) -> 4550 | L22: =SUM(L13:L21) -> 5000 | M22: =SUM(M13:M21) -> 7000 | N22: =SUM(N13:N21) -> 8500 | P22: =SUM(F22:I22) -> 3180 | Q22: =SUM(F22:N22) -> 30950
C25: Capex & Project Curve | E25: year | F25: 2027 | G25: =F25+1 -> 2028 | H25: =G25+1 -> 2029 | I25: =H25+1 -> 2030 | J25: =I25+1 -> 2031 | K25: =J25+1 -> 2032 | L25: =K25+1 -> 2033 | M25: =L25+1 -> 2034 | N25: =M25+1 -> 2035
D26: Capex Cost | E26: $000/MW | F26: 11000 | G26: 10000 | H26: 10000 | I26: 9000 | J26: 9000 | K26: 8500 | L26: 8500 | M26: 7000 | N26: 6300
D27: Project Devex Reimbursement | E27: # | F27: 1 | G27: 1 | H27: 2 | I27: 0 | J27: 0 | K27: 0 | L27: 0 | M27: 0 | N27: 0
D28: Project Capacity Delivered | E28: MW | F28: =F22 -> 30 | G28: =G22 -> 350 | H28: =H22 -> 1150 | I28: =I22 -> 1650 | J28: =J22 -> 2720 | K28: =K22 -> 4550 | L28: =L22 -> 5000 | M28: =M22 -> 7000 | N28: =N22 -> 8500
D29: MW Operational | E29: MW | F29: =SUM($F28:F$28) -> 30 | G29: =SUM($F28:G$28) -> 380 | H29: =SUM($F28:H$28) -> 1530 | I29: =SUM($F28:I$28) -> 3180 | J29: =SUM($F28:J$28) -> 5900 | K29: =SUM($F28:K$28) -> 10450 | L29: =SUM($F28:L$28) -> 15450 | M29: =SUM($F28:M$28) -> 22450 | N29: =SUM($F28:N$28) -> 30950
D31: Project Capex | E31: $m | F31: =F26*F28/1000 -> 330 | G31: =G26*G28/1000 -> 3500 | H31: =H26*H28/1000 -> 11500 | I31: =I26*I28/1000 -> 14850 | J31: =J26*J28/1000 -> 24480 | K31: =K26*K28/1000 -> 38675 | L31: =L26*L28/1000 -> 42500 | M31: =M26*M28/1000 -> 49000 | N31: =N26*N28/1000 -> 53550
B33: Revenue Model & Operating Margin
C35: Fee Structure to XGS
D36: EPCM Fee | E36: % Capex | F36: 0.04
D37: LTSA Fee | E37: $000/MW/yr | F37: 6
C39: Operating Expenses (2027Q2-2028)
D40: Operating Headcount Escalator | E40: % p.a. | F40: 0.3
D41: Operating Expenses Escalator | E41: % p.a. | F41: 0.3
C43: Operating Margin (2029 Onwards)
D44: R&D Spend Growth (vs 2028 Baseline) | E44: % p.a. | F44: 0.1
B46: Devex Assumptions
C48: Reimbursable Devex @ TopCo
D49: Resource evaluation | E49: $000/Project | F49: 750
D50: Subsurface engineering services | E50: $000/Project | F50: 100
D51: Surface engineering services | E51: $000/Project | F51: 335
D52: Other development | E52: $000/Project | F52: 500
D53: Total | E53: $000/Project | F53: =SUM(F49:F52) -> 1685
B55: Other
...

Sheet Consolidated Forecast (A)
B2: XGS Enterprise Model
B3: Consolidated Forecasts (Annual)
B5: Date | E5: =Inputs!$F$7 -> 45322 | G5: =EOMONTH(E5,-1) -> 45291 | H5: =EOMONTH(G5,12) -> 45657 | I5: =EOMONTH(H5,12) -> 46022 | J5: =EOMONTH(I5,12) -> 46387 | K5: =EOMONTH(J5,12) -> 46752 | L5: =EOMONTH(K5,12) -> 47118 | M5: =EOMONTH(L5,12) -> 47483 | N5: =EOMONTH(M5,12) -> 47848 | O5: =EOMONTH(N5,12) -> 48213 | ... S5: =EOMONTH(R5,12) -> 49674 | U5: =I5 -> 46022 | V5: =I5 -> 46022
B6: YearFrac | F6: =SUM(G6:BJ6) -> 138.00278 | H6: =YEARFRAC(H5,G5) -> 1 | I6: =YEARFRAC(I5,H5) -> 1 | J6: =YEARFRAC(J5,I5) -> 1 | K6: =YEARFRAC(K5,J5) -> 1 | L6: =YEARFRAC(L5,K5) -> 1 | M6: =YEARFRAC(M5,L5) -> 1 | N6: =YEARFRAC(N5,M5) -> 1 | O6: =YEARFRAC(O5,N5) -> 1 | ... S6: =YEARFRAC(S5,R5) -> 1 | U6: =YEARFRAC(U5,T5) -> 126.00278 | V6: =YEARFRAC(V5,U5) -> 0
B7: Year | H7: =YEAR(H5) -> 2024 | I7: =YEAR(I5) -> 2025 | J7: =YEAR(J5) -> 2026 | K7: =YEAR(K5) -> 2027 | L7: =YEAR(L5) -> 2028 | M7: =YEAR(M5) -> 2029 | N7: =YEAR(N5) -> 2030 | O7: =YEAR(O5) -> 2031 | ... S7: =YEAR(S5) -> 2035 | U7: =YEAR(U5) -> 2025 | V7: =YEAR(V5) -> 2025
A9: SUMMARY
B11: Projects
C12: MW Reaching COD | D12: MW | F12: =SUM(H12:S12) -> 30950 | H12: =IFERROR(INDEX(Inputs!#REF!,MATCH('Consolidated Forecast (A)'!H$7,Inputs!$F$25:$N$25,0)),0) -> 0 | I12: =I38 -> 0 | J12: =J38 -> 0 | K12: =K38 -> 30 | L12: =L38 -> 350 | M12: =M38 -> 1150 | N12: =N38 -> 1650 | O12: =O38 -> 2720 | P12: =P38 -> 4550 | ... S12: =S38 -> 8500
C13: MW Operational | D13: MW | H13: =IFERROR(INDEX(Inputs!#REF!,MATCH('Consolidated Forecast (A)'!H$7,Inputs!$F$25:$N$25,0)),0) -> 0 | I13: =I39 -> 0 | J13: =J39 -> 0 | K13: =K39 -> 30 | L13: =L39 -> 380 | M13: =M39 -> 1530 | N13: =N39 -> 3180 | O13: =O39 -> 5900 | P13: =P39 -> 10450 | ... S13: =S39 -> 30950
B15: Cash Flows
C16: Revenue | D16: $000 | F16: =SUM(H16:S16) -> 10077320 | H16: =H46 -> 0 | I16: =I46 -> 0 | J16: =J46 -> 0 | K16: =K46 -> 13380 | L16: =L46 -> 142280 | M16: =M46 -> 469180 | N16: =N46 -> 613080 | O16: =O46 -> 1014600 | ... S16: =S46 -> 2327700
C17: Expenses | D17: $000 | F17: =SUM(H17:S17) -> -1982759.9 | H17: =-H55 -> -4320.9147 | I17: =-I55 -> -8192.9836 | J17: =-J55 -> -15293.786 | K17: =-K55 -> -22572.078 | L17: =-L55 -> -29380.111 | M17: =-M55 -> -81800 | N17: =-N55 -> -111600 | O17: =-O55 -> -186600 | ... S17: =-S55 -> -464400
C18: Operating Profit | D18: $000 | F18: =SUM(H18:S18) -> 8094560.1 | H18: =SUM(H16:H17) -> -4320.9147 | I18: =SUM(I16:I17) -> -8192.9836 | J18: =SUM(J16:J17) -> -15293.786 | K18: =SUM(K16:K17) -> -9192.0783 | L18: =SUM(L16:L17) -> 112899.89 | M18: =SUM(M16:M17) -> 387380 | N18: =SUM(N16:N17) -> 501480 | O18: =SUM(O16:O17) -> 828000 | ... S18: =SUM(S16:S17) -> 1863300
C19: Operating Profit Margin | H19: =MAX(IFERROR(H18/H$16,0),0) -> 0 | I19: =MAX(IFERROR(I18/I$16,0),0) -> 0 | J19: =MAX(IFERROR(J18/J$16,0),0) -> 0 | K19: =MAX(IFERROR(K18/K$16,0),0) -> 0 | L19: =MAX(IFERROR(L18/L$16,0),0) -> 0.79350498 | M19: =MAX(IFERROR(M18/M$16,0),0) -> 0.82565327 | N19: =MAX(IFERROR(N18/N$16,0),0) -> 0.81796829 | O19: =MAX(IFERROR(O18/O$16,0),0) -> 0.81608516 | ... S19: =MAX(IFERROR(S18/S$16,0),0) -> 0.80048975
C20: R&D / Cost Reduction | D20: $000 | F20: =SUM(H20:S20) -> -83939.773 | H20: =-H61 -> -10301.761 | I20: =-I61 -> -6626.7779 | J20: =-J61 -> -3722 | K20: =-K61 -> -3994.7021 | L20: =-L61 -> -5184.9521 | M20: =-M61 -> -5703.4473 | N20: =-N61 -> -6273.792 | O20: =-O61 -> -6901.1712 | ... S20: =-S61 -> -10104.005
C21: EBITDA Excl Projects | F21: =SUM(H21:S21) -> 8010620.4 | H21: =SUM(H20,H18) -> -14622.676 | I21: =SUM(I20,I18) -> -14819.762 | J21: =SUM(J20,J18) -> -19015.786 | K21: =SUM(K20,K18) -> -13186.78 | L21: =SUM(L20,L18) -> 107714.94 | M21: =SUM(M20,M18) -> 381676.55 | N21: =SUM(N20,N18) -> 495206.21 | O21: =SUM(O20,O18) -> 821098.83 | ... S21: =SUM(S20,S18) -> 1853196
C22: Non-Project EBITDA Margin | H22: =MAX(IFERROR(H21/H$16,0),0) -> 0 | I22: =MAX(IFERROR(I21/I$16,0),0) -> 0 | J22: =MAX(IFERROR(J21/J$16,0),0) -> 0 | K22: =MAX(IFERROR(K21/K$16,0),0) -> 0 | L22: =MAX(IFERROR(L21/L$16,0),0) -> 0.75706309 | M22: =MAX(IFERROR(M21/M$16,0),0) -> 0.81349706 | N22: =MAX(IFERROR(N21/N$16,0),0) -> 0.80773506 | O22: =MAX(IFERROR(O21/O$16,0),0) -> 0.80928329 | ... S22: =MAX(IFERROR(S21/S$16,0),0) -> 0.79614899
C23: Project Expenses excl Wells | D23: $000 | F23: =SUM(H23:S23) -> -5183.1486 | H23: =-H150 -> -55.8603 | I23: =-I150 -> -424.955 | J23: =-J150 -> -4702.3333 | K23: =-K150 -> 0 | L23: =-L150 -> 0 | M23: =-M151 -> 0 | N23: =-N151 -> 0 | O23: =-O151 -> 0 | P23: =-P151 -> 0 | Q23: =-Q151 -> 0 | R23: =-R151 -> 0 | S23: =-S151 -> 0
C24: EBITDA Incl Projects | F24: =SUM(H24:S24) -> 8005437.2 | H24: =H21+SUM(H23:H23) -> -14678.536 | I24: =I21+SUM(I23:I23) -> -15244.717 | J24: =J21+SUM(J23:J23) -> -23718.119 | K24: =K21+SUM(K23:K23) -> -13186.78 | L24: =L21+SUM(L23:L23) -> 107714.94 | M24: =M21+SUM(M23:M23) -> 381676.55 | N24: =N21+SUM(N23:N23) -> 495206.21 | O24: =O21+SUM(O23:O23) -> 821098.83 | ... S24: =S21+SUM(S23:S23) -> 1853196
C25: EBITDA Margin | H25: =MAX(IFERROR(H24/H$16,0),0) -> 0 | I25: =MAX(IFERROR(I24/I$16,0),0) -> 0 | J25: =MAX(IFERROR(J24/J$16,0),0) -> 0 | K25: =MAX(IFERROR(K24/K$16,0),0) -> 0 | L25: =MAX(IFERROR(L24/L$16,0),0) -> 0.75706309 | M25: =MAX(IFERROR(M24/M$16,0),0) -> 0.81349706 | N25: =MAX(IFERROR(N24/N$16,0),0) -> 0.80773506 | O25: =MAX(IFERROR(O24/O$16,0),0) -> 0.80928329 | ... S25: =MAX(IFERROR(S24/S$16,0),0) -> 0.79614899
C26: Interest Expense | D26: $000 | F26: =SUM(H26:S26) -> -575.96112 | H26: =H81 -> 0 | I26: =I81 -> -212.35 | J26: =J81 -> -213.88889 | K26: =K81 -> -120.55556 | L26: =L81 -> -29.166671 | M26: =M81 -> 0 | N26: =N81 -> 0 | O26: =O81 -> 0 | ... S26: =S81 -> 0
C27: Debt Drawdown / (Repayment) | D27: $000 | F27: =SUM(H27:S27) -> 0 | H27: =H82 -> 0 | I27: =I82 -> 3750 | J27: =J82 -> -1500 | K27: =K82 -> -1500 | L27: =L82 -> -750 | M27: =M82 -> 0 | N27: =N82 -> 0 | O27: =O82 -> 0 | ... S27: =S82 -> 0
C28: Historical Taxes & Interest Income | D28: $000 | F28: =SUM(H28:S28) -> 876.33736 | H28: =H83 -> 635.47403 | I28: =I83 -> 240.86333 | J28: =J83 -> 0 | K28: =K83 -> 0 | L28: =L83 -> 0 | M28: =M83 -> 0 | N28: =N83 -> 0 | O28: =O83 -> 0 | ... S28: =S83 -> 0
C29: Historical Accrual to Cash Adjustments | D29: $000 | F29: =SUM(H29:S29) -> -7225.0317 | H29: =H84 -> -1706.824 | I29: =I84 -> -5518.2077 | J29: =J84 -> 0 | K29: =K84 -> 0 | L29: =L84 -> 0 | M29: =M84 -> 0 | N29: =N84 -> 0 | O29: =O84 -> 0 | ... S29: =S84 -> 0
C30: Net Cash Flow excl Equity Financing | D30: $000 | F30: =SUM(H30:S30) -> 7998512.5 | H30: =SUM(H26:H29,H24) -> -15749.886 | I30: =SUM(I26:I29,I24) -> -16984.411 | J30: =SUM(J26:J29,J24) -> -25432.008 | K30: =SUM(K26:K29,K24) -> -14807.336 | L30: =SUM(L26:L29,L24) -> 106935.77 | M30: =SUM(M26:M29,M24) -> 381676.55 | N30: =SUM(N26:N29,N24) -> 495206.21 | O30: =SUM(O26:O29,O24) -> 821098.83 | ... S30: =SUM(S26:S29,S24) -> 1853196
C31: Historical Equity Injections | D31: $000 | F31: =SUM(H31:S31) -> 33717.499 | H31: =H87 -> 20799.974 | I31: =I87 -> 12917.525 | J31: =J87 -> 0 | K31: =K87 -> 0 | L31: =L87 -> 0 | M31: =M87 -> 0 | N31: =N87 -> 0 | O31: =O87 -> 0 | ... S31: =S87 -> 0
C32: Net Cash Flow | D32: $000 | F32: =SUM(H32:S32) -> 8032230 | H32: =SUM(H30:H31) -> 5050.0877 | I32: =SUM(I30:I31) -> -4066.8859 | J32: =SUM(J30:J31) -> -25432.008 | K32: =SUM(K30:K31) -> -14807.336 | L32: =SUM(L30:L31) -> 106935.77 | M32: =SUM(M30:M31) -> 381676.55 | N32: =SUM(N30:N31) -> 495206.21 | O32: =SUM(O30:O31) -> 821098.83 | ... S32: =SUM(S30:S31) -> 1853196
A34: Project Cadence
B36: Capex Summary
C37: Capex Cost | D37: $000/MW | H37: =IFERROR(INDEX(Inputs!$F26:$N26,MATCH('Consolidated Forecast (A)'!H$7,Inputs!$F$25:$N$25,0)),0) -> 0 | I37: =IFERROR(INDEX(Inputs!$F26:$P26,MATCH('Consolidated Forecast (A)'!I$7,Inputs!$F$25:$P$25,0)),0) -> 0 | J37: =IFERROR(INDEX(Inputs!$F26:$P26,MATCH('Consolidated Forecast (A)'!J$7,Inputs!$F$25:$P$25,0)),0) -> 0 | K37: =IFERROR(INDEX(Inputs!$F26:$P26,MATCH('Consolidated Forecast (A)'!K$7,Inputs!$F$25:$P$25,0)),0) -> 11000 | L37: =IFERROR(INDEX(Inputs!$F26:$P26,MATCH('Consolidated Forecast (A)'!L$7,Inputs!$F$25:$P$25,0)),0) -> 10000 | M37: =IFERROR(INDEX(Inputs!$F26:$P26,MATCH('Consolidated Forecast (A)'!M$7,Inputs!$F$25:$P$25,0)),0) -> 10000 | N37: =IFERROR(INDEX(Inputs!$F26:$P26,MATCH('Consolidated Forecast (A)'!N$7,Inputs!$F$25:$P$25,0)),0) -> 9000 | O37: =IFERROR(INDEX(Inputs!$F26:$P26,MATCH('Consolidated Forecast (A)'!O$7,Inputs!$F$25:$P$25,0)),0) -> 9000 | P37: =IFERROR(INDEX(Inputs!$F26:$P26,MATCH('Consolidated Forecast (A)'!P$7,Inputs!$F$25:$P$25,0)),0) -> 8500 | ... S37: =IFERROR(INDEX(Inputs!$F26:$P26,MATCH('Consolidated Forecast (A)'!S$7,Inputs!$F$25:$P$25,0)),0) -> 6300
C38: MW Reaching COD | D38: MW | F38: =SUM(H38:S38) -> 30950 | H38: =IFERROR(INDEX(Inputs!$F28:$N28,MATCH('Consolidated Forecast (A)'!H$7,Inputs!$F$25:$N$25,0)),0) -> 0 | I38: =IFERROR(INDEX(Inputs!$F28:$P28,MATCH('Consolidated Forecast (A)'!I$7,Inputs!$F$25:$P$25,0)),0) -> 0 | J38: =IFERROR(INDEX(Inputs!$F28:$P28,MATCH('Consolidated Forecast (A)'!J$7,Inputs!$F$25:$P$25,0)),0) -> 0 | K38: =IFERROR(INDEX(Inputs!$F28:$P28,MATCH('Consolidated Forecast (A)'!K$7,Inputs!$F$25:$P$25,0)),0) -> 30 | L38: =IFERROR(INDEX(Inputs!$F28:$P28,MATCH('Consolidated Forecast (A)'!L$7,Inputs!$F$25:$P$25,0)),0) -> 350 | M38: =IFERROR(INDEX(Inputs!$F28:$P28,MATCH('Consolidated Forecast (A)'!M$7,Inputs!$F$25:$P$25,0)),0) -> 1150 | N38: =IFERROR(INDEX(Inputs!$F28:$P28,MATCH('Consolidated Forecast (A)'!N$7,Inputs!$F$25:$P$25,0)),0) -> 1650 | O38: =IFERROR(INDEX(Inputs!$F28:$P28,MATCH('Consolidated Forecast (A)'!O$7,Inputs!$F$25:$P$25,0)),0) -> 2720 | P38: =IFERROR(INDEX(Inputs!$F28:$P28,MATCH('Consolidated Forecast (A)'!P$7,Inputs!$F$25:$P$25,0)),0) -> 4550 | ... S38: =IFERROR(INDEX(Inputs!$F28:$P28,MATCH('Consolidated Forecast (A)'!S$7,Inputs!$F$25:$P$25,0)),0) -> 8500
C39: MW Operational | D39: MW | H39: =IFERROR(INDEX(Inputs!$F29:$N29,MATCH('Consolidated Forecast (A)'!H$7,Inputs!$F$25:$N$25,0)),0) -> 0 | I39: =IFERROR(INDEX(Inputs!$F29:$P29,MATCH('Consolidated Forecast (A)'!I$7,Inputs!$F$25:$P$25,0)),0) -> 0 | J39: =IFERROR(INDEX(Inputs!$F29:$P29,MATCH('Consolidated Forecast (A)'!J$7,Inputs!$F$25:$P$25,0)),0) -> 0 | K39: =IFERROR(INDEX(Inputs!$F29:$P29,MATCH('Consolidated Forecast (A)'!K$7,Inputs!$F$25:$P$25,0)),0) -> 30 | L39: =IFERROR(INDEX(Inputs!$F29:$P29,MATCH('Consolidated Forecast (A)'!L$7,Inputs!$F$25:$P$25,0)),0) -> 380 | M39: =IFERROR(INDEX(Inputs!$F29:$P29,MATCH('Consolidated Forecast (A)'!M$7,Inputs!$F$25:$P$25,0)),0) -> 1530 | N39: =IFERROR(INDEX(Inputs!$F29:$P29,MATCH('Consolidated Forecast (A)'!N$7,Inputs!$F$25:$P$25,0)),0) -> 3180 | O39: =IFERROR(INDEX(Inputs!$F29:$P29,MATCH('Consolidated Forecast (A)'!O$7,Inputs!$F$25:$P$25,0)),0) -> 5900 | P39: =IFERROR(INDEX(Inputs!$F29:$P29,MATCH('Consolidated Forecast (A)'!P$7,Inputs!$F$25:$P$25,0)),0) -> 10450 | ... S39: =IFERROR(INDEX(Inputs!$F29:$P29,MATCH('Consolidated Forecast (A)'!S$7,Inputs!$F$25:$P$25,0)),0) -> 30950
A41: Projections - PnL
B43: Income
C44: EPCM Revenue | D44: $000 | E44: =Inputs!$F$36 -> 0.04 | F44: =SUM(H44:S44) -> 9535400 | H44: =H37*H38*$E$44 -> 0 | I44: =I37*I38*$E$44 -> 0 | J44: =J37*J38*$E$44 -> 0 | K44: =K37*K38*$E$44 -> 13200 | L44: =L37*L38*$E$44 -> 140000 | M44: =M37*M38*$E$44 -> 460000 | N44: =N37*N38*$E$44 -> 594000 | O44: =O37*O38*$E$44 -> 979200 | ... S44: =S37*S38*$E$44 -> 2142000
C45: Ops Management Revenue | D45: $000 | E45: =Inputs!F37 -> 6 | F45: =SUM(H45:S45) -> 541920 | H45: =$E45*H$39 -> 0 | I45: =$E45*I$39 -> 0 | J45: =$E45*J$39 -> 0 | K45: =$E45*K$39 -> 180 | L45: =$E45*L$39 -> 2280 | M45: =$E45*M$39 -> 9180 | N45: =$E45*N$39 -> 19080 | O45: =$E45*O$39 -> 35400 | ... S45: =$E45*S$39 -> 185700
C46: Revenue | D46: $000 | F46: =SUM(H46:S46) -> 10077320 | H46: =SUM(H44:H45) -> 0 | I46: =SUM(I44:I45) -> 0 | J46: =SUM(J44:J45) -> 0 | K46: =SUM(K44:K45) -> 13380 | L46: =SUM(L44:L45) -> 142280 | M46: =SUM(M44:M45) -> 469180 | N46: =SUM(N44:N45) -> 613080 | O46: =SUM(O44:O45) -> 1014600 | ... S46: =SUM(S44:S45) -> 2327700
C47: YoY Revenue Growth | H47: =IFERROR(H46/G46,0) -> 0 | I47: =IFERROR(I46/H46-1,0) -> 0 | J47: =IFERROR(J46/I46-1,0) -> 0 | K47: =IFERROR(K46/J46-1,0) -> 0 | L47: =IFERROR(L46/K46-1,0) -> 9.6337818 | M47: =IFERROR(M46/L46-1,0) -> 2.2975822 | N47: =IFERROR(N46/M46-1,0) -> 0.30670532 | O47: =IFERROR(O46/N46-1,0) -> 0.65492269 | P47: =IFERROR(P46/O46-1,0) -> 0.58653657 | ... S47: =IFERROR(S46/R46-1,0) -> 0.11123311
B49: Expenses
C50: Payroll | D50: $000 | F50: =SUM(H50:S50) -> 40597.773 | H50: =H103 -> 2703.3605 | I50: =I103 -> 5029.6521 | J50: =J103 -> 7211 | K50: =K103 -> 11143.955 | L50: =L103 -> 14509.805 | M50: 0 | N50: 0 | O50: 0 | P50: 0 | Q50: 0 | R50: 0 | S50: 0
...

Sheet ST Forecast (M)
B2: XGS Enterprise Model
B3: Short Term Forecasts (Monthly)
B5: Date | E5: 46022 | G5: =E5 -> 46022 | H5: =EOMONTH(G5,1) -> 46053 | I5: =EOMONTH(H5,1) -> 46081 | J5: =EOMONTH(I5,1) -> 46112 | K5: =EOMONTH(J5,1) -> 46142 | L5: =EOMONTH(K5,1) -> 46173 | M5: =EOMONTH(L5,1) -> 46203 | N5: =EOMONTH(M5,1) -> 46234 | O5: =EOMONTH(N5,1) -> 46265 | ... AQ5: =EOMONTH(AP5,1) -> 47118
B6: YearFrac | F6: =SUM(G6:CE6) -> 2.9944444 | H6: =YEARFRAC(H5,G5) -> 0.083333333 | I6: =YEARFRAC(I5,H5) -> 0.077777778 | J6: =YEARFRAC(J5,I5) -> 0.086111111 | K6: =YEARFRAC(K5,J5) -> 0.083333333 | L6: =YEARFRAC(L5,K5) -> 0.083333333 | M6: =YEARFRAC(M5,L5) -> 0.083333333 | N6: =YEARFRAC(N5,M5) -> 0.083333333 | O6: =YEARFRAC(O5,N5) -> 0.083333333 | ... AQ6: =YEARFRAC(AQ5,AP5) -> 0.083333333
B7: Year End | H7: =DATE(YEAR(H5),12,31) -> 46387 | I7: =DATE(YEAR(I5),12,31) -> 46387 | J7: =DATE(YEAR(J5),12,31) -> 46387 | K7: =DATE(YEAR(K5),12,31) -> 46387 | L7: =DATE(YEAR(L5),12,31) -> 46387 | M7: =DATE(YEAR(M5),12,31) -> 46387 | N7: =DATE(YEAR(N5),12,31) -> 46387 | O7: =DATE(YEAR(O5),12,31) -> 46387 | ... AQ7: =DATE(YEAR(AQ5),12,31) -> 47118
A9: Expense Forecast
B11: Headcount
C12: New Headcount (FTE) | D12: # | H12: 28 | I12: 28 | J12: 29 | K12: 30 | L12: 31 | M12: 32 | N12: 34 | O12: 36 | P12: 38 | Q12: 40 | R12: 42 | S12: 44 | T12: =S12+T13 -> 46 | U12: =T12+U13 -> 48 | V12: 50 | W12: 51 | X12: 52 | Y12: 53 | Z12: 54 | AA12: 55 | AB12: 56 | AC12: 58 | AD12: 59 | AE12: 60 | AF12: 62 | AG12: 63 | AH12: 64 | AI12: 66 | AJ12: 67 | AK12: 69 | AL12: 70 | AM12: 72 | AN12: 73 | AO12: 75 | AP12: 77 | AQ12: 78
C13: Total Headcount (FTE) | D13: # | F13: =SUM(H13:AQ13) -> 50 | H13: 0 | I13: 0 | J13: 1 | K13: 1 | L13: 1 | M13: 1 | N13: 2 | O13: 2 | P13: 2 | Q13: 2 | R13: 2 | S13: 2 | T13: 2 | U13: 2 | V13: 2 | W13: 1 | X13: 1 | Y13: 1 | Z13: 1 | AA13: 1 | AB13: 1 | AC13: 2 | AD13: 1 | AE13: 1 | AF13: 2 | AG13: 1 | AH13: 1 | AI13: 2 | AJ13: 1 | AK13: 2 | AL13: 1 | AM13: 2 | AN13: 1 | AO13: 2 | AP13: 2 | AQ13: 1
B15: SG&A
C16: Payroll | D16: $000 | F16: =SUM(H16:AQ16) -> 32864.76 | H16: 490 | I16: 490 | J16: 508 | K16: 525 | L16: 543 | M16: 560 | N16: 595 | O16: 630 | P16: 665 | Q16: 700 | R16: 735 | S16: 770 | T16: 805 | U16: 840 | V16: =U16*(1+Inputs!$F$40)^V$6 -> 859.19368 | W16: =V16*(1+Inputs!$F$40)^W$6 -> 878.18569 | X16: =W16*(1+Inputs!$F$40)^X$6 -> 897.5975 | Y16: =X16*(1+Inputs!$F$40)^Y$6 -> 917.4384 | Z16: =Y16*(1+Inputs!$F$40)^Z$6 -> 937.71787 | AA16: =Z16*(1+Inputs!$F$40)^AA$6 -> 958.44561 | AB16: =AA16*(1+Inputs!$F$40)^AB$6 -> 979.63152 | AC16: =AB16*(1+Inputs!$F$40)^AC$6 -> 1001.2857 | ... AQ16: =AP16*(1+Inputs!$F$40)^AQ$6 -> 1359.8529
C17: Overhead | D17: $000 | F17: =SUM(H17:AQ17) -> 7237.6436 | H17: 108 | I17: 108 | J17: 112 | K17: 116 | L17: 119 | M17: 123 | N17: 131 | O17: 139 | P17: 146 | Q17: 154 | R17: 162 | S17: 169 | T17: 178 | U17: 185 | V17: =U17*(1+Inputs!$F$40)^V$6 -> 189.22718 | W17: =V17*(1+Inputs!$F$40)^W$6 -> 193.40994 | X17: =W17*(1+Inputs!$F$40)^X$6 -> 197.68516 | Y17: =X17*(1+Inputs!$F$40)^Y$6 -> 202.05489 | Z17: =Y17*(1+Inputs!$F$40)^Z$6 -> 206.5212 | AA17: =Z17*(1+Inputs!$F$40)^AA$6 -> 211.08624 | AB17: =AA17*(1+Inputs!$F$40)^AB$6 -> 215.75218 | AC17: =AB17*(1+Inputs!$F$40)^AC$6 -> 220.52126 | ... AQ17: =AP17*(1+Inputs!$F$40)^AQ$6 -> 299.49142
C19: Software services | D19: $000 | F19: =SUM(H19:AQ19) -> 1096 | H19: 62 | I19: 62 | J19: 64 | K19: 66 | L19: 68 | M19: 70 | N19: 74 | O19: 78 | P19: 82 | Q19: 86 | R19: 90 | S19: 94 | T19: 98 | U19: 102 | V19: 0 | W19: 0 | X19: 0 | Y19: 0 | Z19: 0 | AA19: 0 | AB19: 0 | AC19: 0 | AD19: 0 | AE19: 0 | AF19: 0 | AG19: 0 | AH19: 0 | AI19: 0 | AJ19: 0 | AK19: 0 | AL19: 0 | AM19: 0 | AN19: 0 | AO19: 0 | AP19: 0 | AQ19: 0
C20: Accounting Services (incl software) | D20: $000 | F20: =SUM(H20:AQ20) -> 112 | H20: 6 | I20: 6 | J20: 6 | K20: 15 | L20: 6 | M20: 26 | N20: 10 | O20: 1 | P20: 6 | Q20: 10 | R20: 5 | S20: 5 | T20: 5 | U20: 5 | V20: 0 | W20: 0 | X20: 0 | Y20: 0 | Z20: 0 | AA20: 0 | AB20: 0 | AC20: 0 | AD20: 0 | AE20: 0 | AF20: 0 | AG20: 0 | AH20: 0 | AI20: 0 | AJ20: 0 | AK20: 0 | AL20: 0 | AM20: 0 | AN20: 0 | AO20: 0 | AP20: 0 | AQ20: 0
C21: Audit Services | D21: $000 | F21: =SUM(H21:AQ21) -> 122.5 | H21: 7 | I21: 12.5 | J21: 12.5 | K21: 12.5 | L21: 15.5 | M21: 15.5 | N21: 0 | O21: 0 | P21: 0 | Q21: 0 | R21: 0 | S21: 7 | T21: 20 | U21: 20 | V21: 0 | W21: 0 | X21: 0 | Y21: 0 | Z21: 0 | AA21: 0 | AB21: 0 | AC21: 0 | AD21: 0 | AE21: 0 | AF21: 0 | AG21: 0 | AH21: 0 | AI21: 0 | AJ21: 0 | AK21: 0 | AL21: 0 | AM21: 0 | AN21: 0 | AO21: 0 | AP21: 0 | AQ21: 0
C22: Tax Services | D22: $000 | F22: =SUM(H22:AQ22) -> 102.5 | H22: 0 | I22: 7.5 | J22: 12 | K22: 0 | L22: 7.5 | M22: 12 | N22: 0 | O22: 15 | P22: 0 | Q22: 13 | R22: 13 | S22: 0 | T22: 7.5 | U22: 15 | V22: 0 | W22: 0 | X22: 0 | Y22: 0 | Z22: 0 | AA22: 0 | AB22: 0 | AC22: 0 | AD22: 0 | AE22: 0 | AF22: 0 | AG22: 0 | AH22: 0 | AI22: 0 | AJ22: 0 | AK22: 0 | AL22: 0 | AM22: 0 | AN22: 0 | AO22: 0 | AP22: 0 | AQ22: 0
C23: IT Services | D23: $000 | F23: =SUM(H23:AQ23) -> 234 | H23: 10 | I23: 10 | J23: 10 | K23: 11 | L23: 12 | M23: 13 | N23: 14 | O23: 16 | P23: 18 | Q23: 20 | R23: 22 | S23: 24 | T23: 26 | U23: 28 | V23: 0 | W23: 0 | X23: 0 | Y23: 0 | Z23: 0 | AA23: 0 | AB23: 0 | AC23: 0 | AD23: 0 | AE23: 0 | AF23: 0 | AG23: 0 | AH23: 0 | AI23: 0 | AJ23: 0 | AK23: 0 | AL23: 0 | AM23: 0 | AN23: 0 | AO23: 0 | AP23: 0 | AQ23: 0
C24: Recruiting | D24: $000 | F24: =SUM(H24:AQ24) -> 320 | H24: 0 | I24: 0 | J24: 0 | K24: 0 | L24: 0 | M24: 0 | N24: 40 | O24: 40 | P24: 40 | Q24: 40 | R24: 40 | S24: 40 | T24: 40 | U24: 40 | V24: 0 | W24: 0 | X24: 0 | Y24: 0 | Z24: 0 | AA24: 0 | AB24: 0 | AC24: 0 | AD24: 0 | AE24: 0 | AF24: 0 | AG24: 0 | AH24: 0 | AI24: 0 | AJ24: 0 | AK24: 0 | AL24: 0 | AM24: 0 | AN24: 0 | AO24: 0 | AP24: 0 | AQ24: 0
C25: Overhead Services | D25: $000 | F25: =SUM(H25:AQ25) -> 7989.19 | H25: =SUM(H19:H24) -> 85 | I25: =SUM(I19:I24) -> 98 | J25: =SUM(J19:J24) -> 104.5 | K25: =SUM(K19:K24) -> 104.5 | L25: =SUM(L19:L24) -> 109 | M25: =SUM(M19:M24) -> 136.5 | N25: =SUM(N19:N24) -> 138 | O25: =SUM(O19:O24) -> 150 | ... U25: =SUM(U19:U24) -> 210 | V25: =U25*(1+Inputs!$F$41)^V$6 -> 214.79842 | W25: =V25*(1+Inputs!$F$41)^W$6 -> 219.54642 | X25: =W25*(1+Inputs!$F$41)^X$6 -> 224.39937 | Y25: =X25*(1+Inputs!$F$41)^Y$6 -> 229.3596 | Z25: =Y25*(1+Inputs!$F$41)^Z$6 -> 234.42947 | AA25: =Z25*(1+Inputs!$F$41)^AA$6 -> 239.6114 | AB25: =AA25*(1+Inputs!$F$41)^AB$6 -> 244.90788 | AC25: =AB25*(1+Inputs!$F$41)^AC$6 -> 250.32143 | ... AQ25: =AP25*(1+Inputs!$F$41)^AQ$6 -> 339.96323
C27: Legal Fees - Corporate | D27: $000 | F27: =SUM(H27:AQ27) -> 3484.7256 | H27: 51 | I27: 52 | J27: 52 | K27: 55.714286 | L27: 57.571429 | M27: 59.428571 | N27: 63.142857 | O27: 66.857143 | P27: 70.571429 | Q27: 74.285714 | R27: 78 | S27: 81.714286 | T27: 85.428571 | U27: 89.142857 | V27: =U27*(1+Inputs!$F$41)^V$6 -> 91.179738 | W27: =V27*(1+Inputs!$F$41)^W$6 -> 93.195216 | X27: =W27*(1+Inputs!$F$41)^X$6 -> 95.255245 | Y27: =X27*(1+Inputs!$F$41)^Y$6 -> 97.36081 | Z27: =Y27*(1+Inputs!$F$41)^Z$6 -> 99.512917 | AA27: =Z27*(1+Inputs!$F$41)^AA$6 -> 101.7126 | AB27: =AA27*(1+Inputs!$F$41)^AB$6 -> 103.9609 | AC27: =AB27*(1+Inputs!$F$41)^AC$6 -> 106.25889 | ... AQ27: =AP27*(1+Inputs!$F$41)^AQ$6 -> 144.31092
C28: Legal Fees - Intellectual Property | D28: $000 | F28: =SUM(H28:AQ28) -> 2980.73 | H28: 70 | I28: 70 | J28: 70 | K28: 70 | L28: 70 | M28: 70 | N28: 70 | O28: 70 | P28: 70 | Q28: 70 | R28: 70 | S28: 70 | T28: 70 | U28: 70 | V28: =U28*(1+Inputs!$F$41)^V$6 -> 71.599473 | W28: =V28*(1+Inputs!$F$41)^W$6 -> 73.182141 | X28: =W28*(1+Inputs!$F$41)^X$6 -> 74.799792 | Y28: =X28*(1+Inputs!$F$41)^Y$6 -> 76.4532 | Z28: =Y28*(1+Inputs!$F$41)^Z$6 -> 78.143156 | AA28: =Z28*(1+Inputs!$F$41)^AA$6 -> 79.870467 | AB28: =AA28*(1+Inputs!$F$41)^AB$6 -> 81.63596 | AC28: =AB28*(1+Inputs!$F$41)^AC$6 -> 83.440478 | ... AQ28: =AP28*(1+Inputs!$F$41)^AQ$6 -> 113.32108
C29: Legal Fees - Fundraising | D29: $000 | F29: =SUM(H29:AQ29) -> 300 | H29: 0 | I29: 0 | J29: 300 | K29: 0 | L29: 0 | M29: 0 | N29: 0 | O29: 0 | P29: 0 | Q29: 0 | R29: 0 | S29: 0 | T29: =U29 -> 0 | U29: 0 | V29: 0 | W29: 0 | X29: 0 | Y29: 0 | Z29: 0 | AA29: 0 | AB29: 0 | AC29: 0 | AD29: 0 | AE29: 0 | AF29: 0 | AG29: 0 | AH29: 0 | AI29: 0 | AJ29: 0 | AK29: 0 | AL29: 0 | AM29: 0 | AN29: 0 | AO29: 0 | AP29: 0 | AQ29: 0
C30: Total Legal Fees | D30: $000 | F30: =SUM(F27:F28) -> 6465.4556 | H30: =SUM(H27:H29) -> 121 | I30: =SUM(I27:I29) -> 122 | J30: =SUM(J27:J29) -> 422 | K30: =SUM(K27:K29) -> 125.71429 | L30: =SUM(L27:L29) -> 127.57143 | M30: =SUM(M27:M29) -> 129.42857 | N30: =SUM(N27:N29) -> 133.14286 | O30: =SUM(O27:O29) -> 136.85714 | ... AQ30: =SUM(AQ27:AQ29) -> 257.632
C32: Marketing | D32: $000 | F32: =SUM(H32:AQ32) -> 510.98229 | H32: 12 | I32: 12 | J32: 12 | K32: 12 | L32: 12 | M32: 12 | N32: 12 | O32: 12 | P32: 12 | Q32: 12 | R32: 12 | S32: 12 | T32: 12 | U32: 12 | V32: =U32*(1+Inputs!$F$41)^V$6 -> 12.274195 | W32: =V32*(1+Inputs!$F$41)^W$6 -> 12.54551 | X32: =W32*(1+Inputs!$F$41)^X$6 -> 12.822821 | Y32: =X32*(1+Inputs!$F$41)^Y$6 -> 13.106263 | Z32: =Y32*(1+Inputs!$F$41)^Z$6 -> 13.39597 | AA32: =Z32*(1+Inputs!$F$41)^AA$6 -> 13.69208 | AB32: =AA32*(1+Inputs!$F$41)^AB$6 -> 13.994736 | AC32: =AB32*(1+Inputs!$F$41)^AC$6 -> 14.304082 | ... AQ32: =AP32*(1+Inputs!$F$41)^AQ$6 -> 19.42647
C33: Government Affairs | D33: $000 | F33: =SUM(H33:AQ33) -> 2554.9114 | H33: 60 | I33: 60 | J33: 60 | K33: 60 | L33: 60 | M33: 60 | N33: 60 | O33: 60 | P33: 60 | Q33: 60 | R33: 60 | S33: 60 | T33: 60 | U33: 60 | V33: =U33*(1+Inputs!$F$41)^V$6 -> 61.370977 | W33: =V33*(1+Inputs!$F$41)^W$6 -> 62.727549 | X33: =W33*(1+Inputs!$F$41)^X$6 -> 64.114107 | Y33: =X33*(1+Inputs!$F$41)^Y$6 -> 65.531314 | Z33: =Y33*(1+Inputs!$F$41)^Z$6 -> 66.979848 | AA33: =Z33*(1+Inputs!$F$41)^AA$6 -> 68.460401 | AB33: =AA33*(1+Inputs!$F$41)^AB$6 -> 69.97368 | AC33: =AB33*(1+Inputs!$F$41)^AC$6 -> 71.52041 | ... AQ33: =AP33*(1+Inputs!$F$41)^AQ$6 -> 97.132352
C34: T&E | D34: $000 | F34: =SUM(H34:AQ34) -> 3515.2034 | H34: 56 | I34: 56 | J34: 58 | K34: 60 | L34: 62 | M34: 64 | N34: 68 | O34: 72 | P34: 76 | Q34: 80 | R34: 84 | S34: 88 | T34: 88 | U34: 88 | V34: =U34*(1+Inputs!$F$41)^V$6 -> 90.010767 | W34: =V34*(1+Inputs!$F$41)^W$6 -> 92.000405 | X34: =W34*(1+Inputs!$F$41)^X$6 -> 94.034024 | Y34: =X34*(1+Inputs!$F$41)^Y$6 -> 96.112594 | Z34: =Y34*(1+Inputs!$F$41)^Z$6 -> 98.23711 | AA34: =Z34*(1+Inputs!$F$41)^AA$6 -> 100.40859 | AB34: =AA34*(1+Inputs!$F$41)^AB$6 -> 102.62806 | AC34: =AB34*(1+Inputs!$F$41)^AC$6 -> 104.8966 | ... AQ34: =AP34*(1+Inputs!$F$41)^AQ$6 -> 142.46078
C35: Insurance | D35: $000 | F35: =SUM(H35:AQ35) -> 1787.438 | H35: 41 | I35: 42 | J35: 42 | K35: 42 | L35: 42 | M35: 42 | N35: 42 | O35: 42 | P35: 42 | Q35: 42 | R35: 42 | S35: 42 | T35: 42 | U35: 42 | V35: =U35*(1+Inputs!$F$41)^V$6 -> 42.959684 | W35: =V35*(1+Inputs!$F$41)^W$6 -> 43.909284 | X35: =W35*(1+Inputs!$F$41)^X$6 -> 44.879875 | Y35: =X35*(1+Inputs!$F$41)^Y$6 -> 45.87192 | Z35: =Y35*(1+Inputs!$F$41)^Z$6 -> 46.885893 | AA35: =Z35*(1+Inputs!$F$41)^AA$6 -> 47.92228 | AB35: =AA35*(1+Inputs!$F$41)^AB$6 -> 48.981576 | AC35: =AB35*(1+Inputs!$F$41)^AC$6 -> 50.064287 | ... AQ35: =AP35*(1+Inputs!$F$41)^AQ$6 -> 67.992646
C36: Office | D36: $000 | F36: =SUM(H36:AQ36) -> 4020.3909 | H36: 41 | I36: 46 | J36: 51 | K36: 56 | L36: 61 | M36: 66 | N36: 71 | O36: 76 | P36: 81 | Q36: 86 | R36: 91 | S36: 96 | T36: 100.36364 | U36: 104.72727 | V36: =U36*(1+Inputs!$F$41)^V$6 -> 107.12025 | W36: =V36*(1+Inputs!$F$41)^W$6 -> 109.48809 | X36: =W36*(1+Inputs!$F$41)^X$6 -> 111.90826 | Y36: =X36*(1+Inputs!$F$41)^Y$6 -> 114.38193 | Z36: =Y36*(1+Inputs!$F$41)^Z$6 -> 116.91028 | AA36: =Z36*(1+Inputs!$F$41)^AA$6 -> 119.49452 | AB36: =AA36*(1+Inputs!$F$41)^AB$6 -> 122.13588 | AC36: =AB36*(1+Inputs!$F$41)^AC$6 -> 124.83562 | ... AQ36: =AP36*(1+Inputs!$F$41)^AQ$6 -> 169.54011
C37: Total Other Expenses | D37: $000 | F37: =SUM(H37:AQ37) -> 12388.926 | H37: =SUM(H32:H36) -> 210 | I37: =SUM(I32:I36) -> 216 | J37: =SUM(J32:J36) -> 223 | K37: =SUM(K32:K36) -> 230 | L37: =SUM(L32:L36) -> 237 | M37: =SUM(M32:M36) -> 244 | N37: =SUM(N32:N36) -> 253 | O37: =SUM(O32:O36) -> 262 | ... AQ37: =SUM(AQ32:AQ36) -> 496.55236
C39: Operating Expenses | D39: $000 | F39: =SUM(H39:AQ39) -> 67245.975 | H39: =SUM(H16:H17,H25,H30,H37) -> 1014 | I39: =SUM(I16:I17,I25,I30,I37) -> 1034 | J39: =SUM(J16:J17,J25,J30,J37) -> 1369.5 | K39: =SUM(K16:K17,K25,K30,K37) -> 1101.2143 | L39: =SUM(L16:L17,L25,L30,L37) -> 1135.5714 | M39: =SUM(M16:M17,M25,M30,M37) -> 1192.9286 | N39: =SUM(N16:N17,N25,N30,N37) -> 1250.1429 | O39: =SUM(O16:O17,O25,O30,O37) -> 1317.8571 | ... AQ39: =SUM(AQ16:AQ17,AQ25,AQ30,AQ37) -> 2753.4919
B41: R&D
C42: Cement placement hardware | D42: $000 | F42: =SUM(H42:AQ42) -> 168 | H42: 12 | I42: 12 | J42: 12 | K42: 12 | L42: 12 | M42: 12 | N42: 12 | O42: 12 | P42: 12 | Q42: 12 | R42: 12 | S42: 12 | T42: =U42 -> 12 | U42: 12 | V42: 0 | W42: 0 | X42: 0 | Y42: 0 | Z42: 0 | AA42: 0 | AB42: 0 | AC42: 0 | AD42: 0 | AE42: 0 | AF42: 0 | AG42: 0 | AH42: 0 | AI42: 0 | AJ42: 0 | AK42: 0 | AL42: 0 | AM42: 0 | AN42: 0 | AO42: 0 | AP42: 0 | AQ42: 0
C43: LCZ and sheath cements | D43: $000 | F43: =SUM(H43:AQ43) -> 1633.3333 | H43: 116.66667 | I43: 116.66667 | J43: 116.66667 | K43: 116.66667 | L43: 116.66667 | M43: 116.66667 | N43: 116.66667 | O43: 116.66667 | P43: 116.66667 | Q43: 116.66667 | R43: 116.66667 | S43: 116.66667 | T43: =U43 -> 116.66667 | U43: 116.66667 | V43: 0 | W43: 0 | X43: 0 | Y43: 0 | Z43: 0 | AA43: 0 | AB43: 0 | AC43: 0 | AD43: 0 | AE43: 0 | AF43: 0 | AG43: 0 | AH43: 0 | AI43: 0 | AJ43: 0 | AK43: 0 | AL43: 0 | AM43: 0 | AN43: 0 | AO43: 0 | AP43: 0 | AQ43: 0
C44: VIT & well design | D44: $000 | F44: =SUM(H44:AQ44) -> 280 | H44: 20 | I44: 20 | J44: 20 | K44: 20 | L44: 20 | M44: 20 | N44: 20 | O44: 20 | P44: 20 | Q44: 20 | R44: 20 | S44: 20 | T44: =U44 -> 20 | U44: 20 | V44: 0 | W44: 0 | X44: 0 | Y44: 0 | Z44: 0 | AA44: 0 | AB44: 0 | AC44: 0 | AD44: 0 | AE44: 0 | AF44: 0 | AG44: 0 | AH44: 0 | AI44: 0 | AJ44: 0 | AK44: 0 | AL44: 0 | AM44: 0 | AN44: 0 | AO44: 0 | AP44: 0 | AQ44: 0
C45: Higher temperature drilling | D45: $000 | F45: =SUM(H45:AQ45) -> 294 | H45: 21 | I45: 21 | J45: 21 | K45: 21 | L45: 21 | M45: 21 | N45: 21 | O45: 21 | P45: 21 | Q45: 21 | R45: 21 | S45: 21 | T45: 21 | U45: 21 | V45: 0 | W45: 0 | X45: 0 | Y45: 0 | Z45: 0 | AA45: 0 | AB45: 0 | AC45: 0 | AD45: 0 | AE45: 0 | AF45: 0 | AG45: 0 | AH45: 0 | AI45: 0 | AJ45: 0 | AK45: 0 | AL45: 0 | AM45: 0 | AN45: 0 | AO45: 0 | AP45: 0 | AQ45: 0
C46: Sensors & measurement | D46: $000 | F46: =SUM(H46:AQ46) -> 294 | H46: 21 | I46: 21 | J46: 21 | K46: 21 | L46: 21 | M46: 21 | N46: 21 | O46: 21 | P46: 21 | Q46: 21 | R46: 21 | S46: 21 | T46: 21 | U46: 21 | V46: 0 | W46: 0 | X46: 0 | Y46: 0 | Z46: 0 | AA46: 0 | AB46: 0 | AC46: 0 | AD46: 0 | AE46: 0 | AF46: 0 | AG46: 0 | AH46: 0 | AI46: 0 | AJ46: 0 | AK46: 0 | AL46: 0 | AM46: 0 | AN46: 0 | AO46: 0 | AP46: 0 | AQ46: 0
C47: Perforation sealing | D47: $000 | F47: =SUM(H47:AQ47) -> 308 | H47: 22 | I47: 22 | J47: 22 | K47: 22 | L47: 22 | M47: 22 | N47: 22 | O47: 22 | P47: 22 | Q47: 22 | R47: 22 | S47: 22 | T47: 22 | U47: 22 | V47: 0 | W47: 0 | X47: 0 | Y47: 0 | Z47: 0 | AA47: 0 | AB47: 0 | AC47: 0 | AD47: 0 | AE47: 0 | AF47: 0 | AG47: 0 | AH47: 0 | AI47: 0 | AJ47: 0 | AK47: 0 | AL47: 0 | AM47: 0 | AN47: 0 | AO47: 0 | AP47: 0 | AQ47: 0
C48: On-site testing cells | D48: $000 | F48: =SUM(H48:AQ48) -> 116.66667 | H48: 8.3333333 | I48: 8.3333333 | J48: 8.3333333 | K48: 8.3333333 | L48: 8.3333333 | M48: 8.3333333 | N48: 8.3333333 | O48: 8.3333333 | P48: 8.3333333 | Q48: 8.3333333 | R48: 8.3333333 | S48: 8.3333333 | T48: =U48 -> 8.3333333 | U48: 8.3333333 | V48: 0 | W48: 0 | X48: 0 | Y48: 0 | Z48: 0 | AA48: 0 | AB48: 0 | AC48: 0 | AD48: 0 | AE48: 0 | AF48: 0 | AG48: 0 | AH48: 0 | AI48: 0 | AJ48: 0 | AK48: 0 | AL48: 0 | AM48: 0 | AN48: 0 | AO48: 0 | AP48: 0 | AQ48: 0
C49: Heat flow modeling software | D49: $000 | F49: =SUM(H49:AQ49) -> 840 | H49: 60 | I49: 60 | J49: 60 | K49: 60 | L49: 60 | M49: 60 | N49: 60 | O49: 60 | P49: 60 | Q49: 60 | R49: 60 | S49: 60 | T49: =U49 -> 60 | U49: 60 | V49: 0 | W49: 0 | X49: 0 | Y49: 0 | Z49: 0 | AA49: 0 | AB49: 0 | AC49: 0 | AD49: 0 | AE49: 0 | AF49: 0 | AG49: 0 | AH49: 0 | AI49: 0 | AJ49: 0 | AK49: 0 | AL49: 0 | AM49: 0 | AN49: 0 | AO49: 0 | AP49: 0 | AQ49: 0
C50: Drilling management software | D50: $000 | F50: =SUM(H50:AQ50) -> 233.33333 | H50: 16.666667 | I50: 16.666667 | J50: 16.666667 | K50: 16.666667 | L50: 16.666667 | M50: 16.666667 | N50: 16.666667 | O50: 16.666667 | P50: 16.666667 | Q50: 16.666667 | R50: 16.666667 | S50: 16.666667 | T50: =U50 -> 16.666667 | U50: 16.666667 | V50: 0 | W50: 0 | X50: 0 | Y50: 0 | Z50: 0 | AA50: 0 | AB50: 0 | AC50: 0 | AD50: 0 | AE50: 0 | AF50: 0 | AG50: 0 | AH50: 0 | AI50: 0 | AJ50: 0 | AK50: 0 | AL50: 0 | AM50: 0 | AN50: 0 | AO50: 0 | AP50: 0 | AQ50: 0
...

Sheet Historical PnL (M)
B2: XGS Enterprise Model
B3: Historical PnL (Monthly)
B5: Date | E5: =Inputs!$F$7 -> 45322 | G5: =EOMONTH(E5,-1) -> 45291 | H5: =EOMONTH(G5,1) -> 45322 | I5: =EOMONTH(H5,1) -> 45351 | J5: =EOMONTH(I5,1) -> 45382 | K5: =EOMONTH(J5,1) -> 45412 | L5: =EOMONTH(K5,1) -> 45443 | M5: =EOMONTH(L5,1) -> 45473 | N5: =EOMONTH(M5,1) -> 45504 | O5: =EOMONTH(N5,1) -> 45535 | ... AE5: =EOMONTH(AD5,1) -> 46022
B6: YearFrac | F6: =SUM(G6:BS6) -> 1.9972222 | H6: =YEARFRAC(H5,G5) -> 0.083333333 | I6: =YEARFRAC(I5,H5) -> 0.080555556 | J6: =YEARFRAC(J5,I5) -> 0.086111111 | K6: =YEARFRAC(K5,J5) -> 0.083333333 | L6: =YEARFRAC(L5,K5) -> 0.083333333 | M6: =YEARFRAC(M5,L5) -> 0.083333333 | N6: =YEARFRAC(N5,M5) -> 0.083333333 | O6: =YEARFRAC(O5,N5) -> 0.083333333 | ... AE6: =YEARFRAC(AE5,AD5) -> 0.083333333
B7: Year End | H7: =DATE(YEAR(H5),12,31) -> 45657 | I7: =DATE(YEAR(I5),12,31) -> 45657 | J7: =DATE(YEAR(J5),12,31) -> 45657 | K7: =DATE(YEAR(K5),12,31) -> 45657 | L7: =DATE(YEAR(L5),12,31) -> 45657 | M7: =DATE(YEAR(M5),12,31) -> 45657 | N7: =DATE(YEAR(N5),12,31) -> 45657 | O7: =DATE(YEAR(O5),12,31) -> 45657 | ... AE7: =DATE(YEAR(AE5),12,31) -> 46022
A9: Operating Profit
B11: Revenue | E11: SOURCE
C12: Revenue | D12: $000 | E12: I/S | F12: =SUM(H12:AE12) -> 0 | H12: =INDEX(_HistIS_M_Data,MATCH($C12,_HistIS_M_Labels,0),MATCH(H$5,_HistIS_M_MonthEnd,0))/1000 -> 0 | I12: =INDEX(_HistIS_M_Data,MATCH($C12,_HistIS_M_Labels,0),MATCH(I$5,_HistIS_M_MonthEnd,0)) -> 0 | J12: =INDEX(_HistIS_M_Data,MATCH($C12,_HistIS_M_Labels,0),MATCH(J$5,_HistIS_M_MonthEnd,0)) -> 0 | K12: =INDEX(_HistIS_M_Data,MATCH($C12,_HistIS_M_Labels,0),MATCH(K$5,_HistIS_M_MonthEnd,0)) -> 0 | L12: =INDEX(_HistIS_M_Data,MATCH($C12,_HistIS_M_Labels,0),MATCH(L$5,_HistIS_M_MonthEnd,0)) -> 0 | M12: =INDEX(_HistIS_M_Data,MATCH($C12,_HistIS_M_Labels,0),MATCH(M$5,_HistIS_M_MonthEnd,0)) -> 0 | N12: =INDEX(_HistIS_M_Data,MATCH($C12,_HistIS_M_Labels,0),MATCH(N$5,_HistIS_M_MonthEnd,0)) -> 0 | O12: =INDEX(_HistIS_M_Data,MATCH($C12,_HistIS_M_Labels,0),MATCH(O$5,_HistIS_M_MonthEnd,0)) -> 0 | P12: =INDEX(_HistIS_M_Data,MATCH($C12,_HistIS_M_Labels,0),MATCH(P$5,_HistIS_M_MonthEnd,0)) -> 0 | ... AE12: =INDEX(_HistIS_M_Data,MATCH($C12,_HistIS_M_Labels,0),MATCH(AE$5,_HistIS_M_MonthEnd,0)) -> 0
B14: SG&A
C15: New Headcount (FTE)
C16: Total Headcount (FTE)
C18: Payroll | D18: $000 | E18: I/S | F18: =SUM(H18:AE18) -> 7733.0126 | H18: =SUMIFS(INDEX(_HistIS_M_Data,0,MATCH(H$5,_HistIS_M_MonthEnd,0)),_HistIS_M_Labels,$C18)/1000 -> 267.3705 | I18: =SUMIFS(INDEX(_HistIS_M_Data,0,MATCH(I$5,_HistIS_M_MonthEnd,0)),_HistIS_M_Labels,$C18)/1000 -> 294.41314 | J18: =SUMIFS(INDEX(_HistIS_M_Data,0,MATCH(J$5,_HistIS_M_MonthEnd,0)),_HistIS_M_Labels,$C18)/1000 -> 160.39341 | K18: =SUMIFS(INDEX(_HistIS_M_Data,0,MATCH(K$5,_HistIS_M_MonthEnd,0)),_HistIS_M_Labels,$C18)/1000 -> 143.95634 | L18: =SUMIFS(INDEX(_HistIS_M_Data,0,MATCH(L$5,_HistIS_M_MonthEnd,0)),_HistIS_M_Labels,$C18)/1000 -> 261.99758 | M18: =SUMIFS(INDEX(_HistIS_M_Data,0,MATCH(M$5,_HistIS_M_MonthEnd,0)),_HistIS_M_Labels,$C18)/1000 -> 151.31328 | N18: =SUMIFS(INDEX(_HistIS_M_Data,0,MATCH(N$5,_HistIS_M_MonthEnd,0)),_HistIS_M_Labels,$C18)/1000 -> 217.7044 | O18: =SUMIFS(INDEX(_HistIS_M_Data,0,MATCH(O$5,_HistIS_M_MonthEnd,0)),_HistIS_M_Labels,$C18)/1000 -> 204.98362 | ... AE18: =SUMIFS(INDEX(_HistIS_M_Data,0,MATCH(AE$5,_HistIS_M_MonthEnd,0)),_HistIS_M_Labels,$C18)/1000 -> 511.714
C19: Overhead | D19: $000 | E19: I/S | F19: =SUM(H19:AE19) -> 339.44912 | H19: =SUMIFS(INDEX(_HistIS_M_Data,0,MATCH(H$5,_HistIS_M_MonthEnd,0)),_HistIS_M_Labels,$C19)/1000 -> 14.491 | I19: =SUMIFS(INDEX(_HistIS_M_Data,0,MATCH(I$5,_HistIS_M_MonthEnd,0)),_HistIS_M_Labels,$C19)/1000 -> 12.28007 | J19: =SUMIFS(INDEX(_HistIS_M_Data,0,MATCH(J$5,_HistIS_M_MonthEnd,0)),_HistIS_M_Labels,$C19)/1000 -> 11.73929 | K19: =SUMIFS(INDEX(_HistIS_M_Data,0,MATCH(K$5,_HistIS_M_MonthEnd,0)),_HistIS_M_Labels,$C19)/1000 -> 6.56512 | L19: =SUMIFS(INDEX(_HistIS_M_Data,0,MATCH(L$5,_HistIS_M_MonthEnd,0)),_HistIS_M_Labels,$C19)/1000 -> 9.13051 | M19: =SUMIFS(INDEX(_HistIS_M_Data,0,MATCH(M$5,_HistIS_M_MonthEnd,0)),_HistIS_M_Labels,$C19)/1000 -> 9.71567 | N19: =SUMIFS(INDEX(_HistIS_M_Data,0,MATCH(N$5,_HistIS_M_MonthEnd,0)),_HistIS_M_Labels,$C19)/1000 -> 11.31257 | O19: =SUMIFS(INDEX(_HistIS_M_Data,0,MATCH(O$5,_HistIS_M_MonthEnd,0)),_HistIS_M_Labels,$C19)/1000 -> 14.88367 | ... AE19: =SUMIFS(INDEX(_HistIS_M_Data,0,MATCH(AE$5,_HistIS_M_MonthEnd,0)),_HistIS_M_Labels,$C19)/1000 -> 25.067
C21: Subject Matter experts | D21: $000 | E21: I/S | F21: =SUM(H21:AE21) -> 142 | H21: =SUMIFS(INDEX(_HistIS_M_Data,0,MATCH(H$5,_HistIS_M_MonthEnd,0)),_HistIS_M_Labels,$C21)/1000 -> 20 | I21: =SUMIFS(INDEX(_HistIS_M_Data,0,MATCH(I$5,_HistIS_M_MonthEnd,0)),_HistIS_M_Labels,$C21)/1000 -> 20 | J21: =SUMIFS(INDEX(_HistIS_M_Data,0,MATCH(J$5,_HistIS_M_MonthEnd,0)),_HistIS_M_Labels,$C21)/1000 -> 20 | K21: =SUMIFS(INDEX(_HistIS_M_Data,0,MATCH(K$5,_HistIS_M_MonthEnd,0)),_HistIS_M_Labels,$C21)/1000 -> 20 | L21: =SUMIFS(INDEX(_HistIS_M_Data,0,MATCH(L$5,_HistIS_M_MonthEnd,0)),_HistIS_M_Labels,$C21)/1000 -> 20 | M21: =SUMIFS(INDEX(_HistIS_M_Data,0,MATCH(M$5,_HistIS_M_MonthEnd,0)),_HistIS_M_Labels,$C21)/1000 -> 9 | N21: =SUMIFS(INDEX(_HistIS_M_Data,0,MATCH(N$5,_HistIS_M_MonthEnd,0)),_HistIS_M_Labels,$C21)/1000 -> 0 | O21: =SUMIFS(INDEX(_HistIS_M_Data,0,MATCH(O$5,_HistIS_M_MonthEnd,0)),_HistIS_M_Labels,$C21)/1000 -> 0 | ... AE21: =SUMIFS(INDEX(_HistIS_M_Data,0,MATCH(AE$5,_HistIS_M_MonthEnd,0)),_HistIS_M_Labels,$C21)/1000 -> 0
C22: Eng services | D22: $000 | E22: I/S | F22: =SUM(H22:AE22) -> 279.51359 | H22: =SUMIFS(INDEX(_HistIS_M_Data,0,MATCH(H$5,_HistIS_M_MonthEnd,0)),_HistIS_M_Labels,$C22)/1000 -> 6.825 | I22: =SUMIFS(INDEX(_HistIS_M_Data,0,MATCH(I$5,_HistIS_M_MonthEnd,0)),_HistIS_M_Labels,$C22)/1000 -> 6.9375 | J22: =SUMIFS(INDEX(_HistIS_M_Data,0,MATCH(J$5,_HistIS_M_MonthEnd,0)),_HistIS_M_Labels,$C22)/1000 -> 10.5 | K22: =SUMIFS(INDEX(_HistIS_M_Data,0,MATCH(K$5,_HistIS_M_MonthEnd,0)),_HistIS_M_Labels,$C22)/1000 -> 31.80059 | L22: =SUMIFS(INDEX(_HistIS_M_Data,0,MATCH(L$5,_HistIS_M_MonthEnd,0)),_HistIS_M_Labels,$C22)/1000 -> 43.6375 | M22: =SUMIFS(INDEX(_HistIS_M_Data,0,MATCH(M$5,_HistIS_M_MonthEnd,0)),_HistIS_M_Labels,$C22)/1000 -> 0 | N22: =SUMIFS(INDEX(_HistIS_M_Data,0,MATCH(N$5,_HistIS_M_MonthEnd,0)),_HistIS_M_Labels,$C22)/1000 -> 7 | O22: =SUMIFS(INDEX(_HistIS_M_Data,0,MATCH(O$5,_HistIS_M_MonthEnd,0)),_HistIS_M_Labels,$C22)/1000 -> 31.575 | ... AE22: =SUMIFS(INDEX(_HistIS_M_Data,0,MATCH(AE$5,_HistIS_M_MonthEnd,0)),_HistIS_M_Labels,$C22)/1000 -> 0
C23: Software services | D23: $000 | E23: I/S | F23: =SUM(H23:AE23) -> 130.63304 | H23: =SUMIFS(INDEX(_HistIS_M_Data,0,MATCH(H$5,_HistIS_M_MonthEnd,0)),_HistIS_M_Labels,$C23)/1000 -> 0 | I23: =SUMIFS(INDEX(_HistIS_M_Data,0,MATCH(I$5,_HistIS_M_MonthEnd,0)),_HistIS_M_Labels,$C23)/1000 -> 0 | J23: =SUMIFS(INDEX(_HistIS_M_Data,0,MATCH(J$5,_HistIS_M_MonthEnd,0)),_HistIS_M_Labels,$C23)/1000 -> 0 | K23: =SUMIFS(INDEX(_HistIS_M_Data,0,MATCH(K$5,_HistIS_M_MonthEnd,0)),_HistIS_M_Labels,$C23)/1000 -> 0 | L23: =SUMIFS(INDEX(_HistIS_M_Data,0,MATCH(L$5,_HistIS_M_MonthEnd,0)),_HistIS_M_Labels,$C23)/1000 -> 1.34 | M23: =SUMIFS(INDEX(_HistIS_M_Data,0,MATCH(M$5,_HistIS_M_MonthEnd,0)),_HistIS_M_Labels,$C23)/1000 -> 0 | N23: =SUMIFS(INDEX(_HistIS_M_Data,0,MATCH(N$5,_HistIS_M_MonthEnd,0)),_HistIS_M_Labels,$C23)/1000 -> 0 | O23: =SUMIFS(INDEX(_HistIS_M_Data,0,MATCH(O$5,_HistIS_M_MonthEnd,0)),_HistIS_M_Labels,$C23)/1000 -> 0 | ... AE23: =SUMIFS(INDEX(_HistIS_M_Data,0,MATCH(AE$5,_HistIS_M_MonthEnd,0)),_HistIS_M_Labels,$C23)/1000 -> 0
C24: Accounting Services (incl software) | D24: $000 | E24: I/S | F24: =SUM(H24:AE24) -> 81.042 | H24: =SUMIFS(INDEX(_HistIS_M_Data,0,MATCH(H$5,_HistIS_M_MonthEnd,0)),_HistIS_M_Labels,$C24)/1000 -> 0 | I24: =SUMIFS(INDEX(_HistIS_M_Data,0,MATCH(I$5,_HistIS_M_MonthEnd,0)),_HistIS_M_Labels,$C24)/1000 -> 0 | J24: =SUMIFS(INDEX(_HistIS_M_Data,0,MATCH(J$5,_HistIS_M_MonthEnd,0)),_HistIS_M_Labels,$C24)/1000 -> 0 | K24: =SUMIFS(INDEX(_HistIS_M_Data,0,MATCH(K$5,_HistIS_M_MonthEnd,0)),_HistIS_M_Labels,$C24)/1000 -> 0 | L24: =SUMIFS(INDEX(_HistIS_M_Data,0,MATCH(L$5,_HistIS_M_MonthEnd,0)),_HistIS_M_Labels,$C24)/1000 -> 0 | M24: =SUMIFS(INDEX(_HistIS_M_Data,0,MATCH(M$5,_HistIS_M_MonthEnd,0)),_HistIS_M_Labels,$C24)/1000 -> 0 | N24: =SUMIFS(INDEX(_HistIS_M_Data,0,MATCH(N$5,_HistIS_M_MonthEnd,0)),_HistIS_M_Labels,$C24)/1000 -> 0 | O24: =SUMIFS(INDEX(_HistIS_M_Data,0,MATCH(O$5,_HistIS_M_MonthEnd,0)),_HistIS_M_Labels,$C24)/1000 -> 0 | ... AE24: =SUMIFS(INDEX(_HistIS_M_Data,0,MATCH(AE$5,_HistIS_M_MonthEnd,0)),_HistIS_M_Labels,$C24)/1000 -> 15.6
C25: PR | D25: $000 | E25: I/S | F25: =SUM(H25:AE25) -> 462.85806 | H25: =SUMIFS(INDEX(_HistIS_M_Data,0,MATCH(H$5,_HistIS_M_MonthEnd,0)),_HistIS_M_Labels,$C25)/1000 -> 7.91796 | I25: =SUMIFS(INDEX(_HistIS_M_Data,0,MATCH(I$5,_HistIS_M_MonthEnd,0)),_HistIS_M_Labels,$C25)/1000 -> 27.08748 | J25: =SUMIFS(INDEX(_HistIS_M_Data,0,MATCH(J$5,_HistIS_M_MonthEnd,0)),_HistIS_M_Labels,$C25)/1000 -> 26.7164 | K25: =SUMIFS(INDEX(_HistIS_M_Data,0,MATCH(K$5,_HistIS_M_MonthEnd,0)),_HistIS_M_Labels,$C25)/1000 -> 80.72572 | L25: =SUMIFS(INDEX(_HistIS_M_Data,0,MATCH(L$5,_HistIS_M_MonthEnd,0)),_HistIS_M_Labels,$C25)/1000 -> 32.70528 | M25: =SUMIFS(INDEX(_HistIS_M_Data,0,MATCH(M$5,_HistIS_M_MonthEnd,0)),_HistIS_M_Labels,$C25)/1000 -> 38.58767 | N25: =SUMIFS(INDEX(_HistIS_M_Data,0,MATCH(N$5,_HistIS_M_MonthEnd,0)),_HistIS_M_Labels,$C25)/1000 -> 44.9655 | O25: =SUMIFS(INDEX(_HistIS_M_Data,0,MATCH(O$5,_HistIS_M_MonthEnd,0)),_HistIS_M_Labels,$C25)/1000 -> 18.99777 | ... AE25: =SUMIFS(INDEX(_HistIS_M_Data,0,MATCH(AE$5,_HistIS_M_MonthEnd,0)),_HistIS_M_Labels,$C25)/1000 -> 0
C26: Audit Services | D26: $000 | E26: I/S | F26: =SUM(H26:AE26) -> 169.0119 | H26: =SUMIFS(INDEX(_HistIS_M_Data,0,MATCH(H$5,_HistIS_M_MonthEnd,0)),_HistIS_M_Labels,$C26)/1000 -> 0 | I26: =SUMIFS(INDEX(_HistIS_M_Data,0,MATCH(I$5,_HistIS_M_MonthEnd,0)),_HistIS_M_Labels,$C26)/1000 -> 0 | J26: =SUMIFS(INDEX(_HistIS_M_Data,0,MATCH(J$5,_HistIS_M_MonthEnd,0)),_HistIS_M_Labels,$C26)/1000 -> 0 | K26: =SUMIFS(INDEX(_HistIS_M_Data,0,MATCH(K$5,_HistIS_M_MonthEnd,0)),_HistIS_M_Labels,$C26)/1000 -> 0 | L26: =SUMIFS(INDEX(_HistIS_M_Data,0,MATCH(L$5,_HistIS_M_MonthEnd,0)),_HistIS_M_Labels,$C26)/1000 -> 0 | M26: =SUMIFS(INDEX(_HistIS_M_Data,0,MATCH(M$5,_HistIS_M_MonthEnd,0)),_HistIS_M_Labels,$C26)/1000 -> 0 | N26: =SUMIFS(INDEX(_HistIS_M_Data,0,MATCH(N$5,_HistIS_M_MonthEnd,0)),_HistIS_M_Labels,$C26)/1000 -> 0 | O26: =SUMIFS(INDEX(_HistIS_M_Data,0,MATCH(O$5,_HistIS_M_MonthEnd,0)),_HistIS_M_Labels,$C26)/1000 -> 0 | ... AE26: =SUMIFS(INDEX(_HistIS_M_Data,0,MATCH(AE$5,_HistIS_M_MonthEnd,0)),_HistIS_M_Labels,$C26)/1000 -> 0.036
C27: Tax Services | D27: $000 | E27: I/S | F27: =SUM(H27:AE27) -> 17.987 | H27: =SUMIFS(INDEX(_HistIS_M_Data,0,MATCH(H$5,_HistIS_M_MonthEnd,0)),_HistIS_M_Labels,$C27)/1000 -> 0 | I27: =SUMIFS(INDEX(_HistIS_M_Data,0,MATCH(I$5,_HistIS_M_MonthEnd,0)),_HistIS_M_Labels,$C27)/1000 -> 0 | J27: =SUMIFS(INDEX(_HistIS_M_Data,0,MATCH(J$5,_HistIS_M_MonthEnd,0)),_HistIS_M_Labels,$C27)/1000 -> 0 | K27: =SUMIFS(INDEX(_HistIS_M_Data,0,MATCH(K$5,_HistIS_M_MonthEnd,0)),_HistIS_M_Labels,$C27)/1000 -> 0 | L27: =SUMIFS(INDEX(_HistIS_M_Data,0,MATCH(L$5,_HistIS_M_MonthEnd,0)),_HistIS_M_Labels,$C27)/1000 -> 0 | M27: =SUMIFS(INDEX(_HistIS_M_Data,0,MATCH(M$5,_HistIS_M_MonthEnd,0)),_HistIS_M_Labels,$C27)/1000 -> 0 | N27: =SUMIFS(INDEX(_HistIS_M_Data,0,MATCH(N$5,_HistIS_M_MonthEnd,0)),_HistIS_M_Labels,$C27)/1000 -> 0 | O27: =SUMIFS(INDEX(_HistIS_M_Data,0,MATCH(O$5,_HistIS_M_MonthEnd,0)),_HistIS_M_Labels,$C27)/1000 -> 0 | ... AE27: =SUMIFS(INDEX(_HistIS_M_Data,0,MATCH(AE$5,_HistIS_M_MonthEnd,0)),_HistIS_M_Labels,$C27)/1000 -> 0
C28: IT Services | D28: $000 | E28: I/S | F28: =SUM(H28:AE28) -> 45.23653 | H28: =SUMIFS(INDEX(_HistIS_M_Data,0,MATCH(H$5,_HistIS_M_MonthEnd,0)),_HistIS_M_Labels,$C28)/1000 -> 0 | I28: =SUMIFS(INDEX(_HistIS_M_Data,0,MATCH(I$5,_HistIS_M_MonthEnd,0)),_HistIS_M_Labels,$C28)/1000 -> 0 | J28: =SUMIFS(INDEX(_HistIS_M_Data,0,MATCH(J$5,_HistIS_M_MonthEnd,0)),_HistIS_M_Labels,$C28)/1000 -> 0 | K28: =SUMIFS(INDEX(_HistIS_M_Data,0,MATCH(K$5,_HistIS_M_MonthEnd,0)),_HistIS_M_Labels,$C28)/1000 -> 0 | L28: =SUMIFS(INDEX(_HistIS_M_Data,0,MATCH(L$5,_HistIS_M_MonthEnd,0)),_HistIS_M_Labels,$C28)/1000 -> 0 | M28: =SUMIFS(INDEX(_HistIS_M_Data,0,MATCH(M$5,_HistIS_M_MonthEnd,0)),_HistIS_M_Labels,$C28)/1000 -> 0 | N28: =SUMIFS(INDEX(_HistIS_M_Data,0,MATCH(N$5,_HistIS_M_MonthEnd,0)),_HistIS_M_Labels,$C28)/1000 -> 0 | O28: =SUMIFS(INDEX(_HistIS_M_Data,0,MATCH(O$5,_HistIS_M_MonthEnd,0)),_HistIS_M_Labels,$C28)/1000 -> 0 | ... AE28: =SUMIFS(INDEX(_HistIS_M_Data,0,MATCH(AE$5,_HistIS_M_MonthEnd,0)),_HistIS_M_Labels,$C28)/1000 -> 3.906
C29: Other Consultants | D29: $000 | E29: I/S | F29: =SUM(H29:AE29) -> 220.667 | H29: =SUMIFS(INDEX(_HistIS_M_Data,0,MATCH(H$5,_HistIS_M_MonthEnd,0)),_HistIS_M_Labels,$C29)/1000 -> 0 | I29: =SUMIFS(INDEX(_HistIS_M_Data,0,MATCH(I$5,_HistIS_M_MonthEnd,0)),_HistIS_M_Labels,$C29)/1000 -> 0 | J29: =SUMIFS(INDEX(_HistIS_M_Data,0,MATCH(J$5,_HistIS_M_MonthEnd,0)),_HistIS_M_Labels,$C29)/1000 -> 0 | K29: =SUMIFS(INDEX(_HistIS_M_Data,0,MATCH(K$5,_HistIS_M_MonthEnd,0)),_HistIS_M_Labels,$C29)/1000 -> 0 | L29: =SUMIFS(INDEX(_HistIS_M_Data,0,MATCH(L$5,_HistIS_M_MonthEnd,0)),_HistIS_M_Labels,$C29)/1000 -> 0 | M29: =SUMIFS(INDEX(_HistIS_M_Data,0,MATCH(M$5,_HistIS_M_MonthEnd,0)),_HistIS_M_Labels,$C29)/1000 -> 0 | N29: =SUMIFS(INDEX(_HistIS_M_Data,0,MATCH(N$5,_HistIS_M_MonthEnd,0)),_HistIS_M_Labels,$C29)/1000 -> 0 | O29: =SUMIFS(INDEX(_HistIS_M_Data,0,MATCH(O$5,_HistIS_M_MonthEnd,0)),_HistIS_M_Labels,$C29)/1000 -> 0 | ... AE29: =SUMIFS(INDEX(_HistIS_M_Data,0,MATCH(AE$5,_HistIS_M_MonthEnd,0)),_HistIS_M_Labels,$C29)/1000 -> 0
C30: Overhead Services | D30: $000 | F30: =SUM(H30:AE30) -> 1548.9491 | H30: =SUM(H21:H29) -> 34.74296 | I30: =SUM(I21:I29) -> 54.02498 | J30: =SUM(J21:J29) -> 57.2164 | K30: =SUM(K21:K29) -> 132.52631 | L30: =SUM(L21:L29) -> 97.68278 | M30: =SUM(M21:M29) -> 47.58767 | N30: =SUM(N21:N29) -> 51.9655 | O30: =SUM(O21:O29) -> 50.57277 | ... AE30: =SUM(AE21:AE29) -> 19.542
C32: Legal Fees - Corporate | D32: $000 | E32: I/S | F32: =SUM(H32:AE32) -> 453.61444 | H32: =SUMIFS(INDEX(_HistIS_M_Data,0,MATCH(H$5,_HistIS_M_MonthEnd,0)),_HistIS_M_Labels,$C32)/1000 -> 0.3785 | I32: =SUMIFS(INDEX(_HistIS_M_Data,0,MATCH(I$5,_HistIS_M_MonthEnd,0)),_HistIS_M_Labels,$C32)/1000 -> 14.918 | J32: =SUMIFS(INDEX(_HistIS_M_Data,0,MATCH(J$5,_HistIS_M_MonthEnd,0)),_HistIS_M_Labels,$C32)/1000 -> 2.61 | K32: =SUMIFS(INDEX(_HistIS_M_Data,0,MATCH(K$5,_HistIS_M_MonthEnd,0)),_HistIS_M_Labels,$C32)/1000 -> 13.077 | L32: =SUMIFS(INDEX(_HistIS_M_Data,0,MATCH(L$5,_HistIS_M_MonthEnd,0)),_HistIS_M_Labels,$C32)/1000 -> 21.4765 | M32: =SUMIFS(INDEX(_HistIS_M_Data,0,MATCH(M$5,_HistIS_M_MonthEnd,0)),_HistIS_M_Labels,$C32)/1000 -> 6.267 | N32: =SUMIFS(INDEX(_HistIS_M_Data,0,MATCH(N$5,_HistIS_M_MonthEnd,0)),_HistIS_M_Labels,$C32)/1000 -> 3.27045 | O32: =SUMIFS(INDEX(_HistIS_M_Data,0,MATCH(O$5,_HistIS_M_MonthEnd,0)),_HistIS_M_Labels,$C32)/1000 -> 8.297 | ... AE32: =SUMIFS(INDEX(_HistIS_M_Data,0,MATCH(AE$5,_HistIS_M_MonthEnd,0)),_HistIS_M_Labels,$C32)/1000 -> 41.716
C33: Legal Fees - Intellectual Property | D33: $000 | E33: I/S | F33: =SUM(H33:AE33) -> 64.41105 | H33: =SUMIFS(INDEX(_HistIS_M_Data,0,MATCH(H$5,_HistIS_M_MonthEnd,0)),_HistIS_M_Labels,$C33)/1000 -> 0.00013 | I33: =SUMIFS(INDEX(_HistIS_M_Data,0,MATCH(I$5,_HistIS_M_MonthEnd,0)),_HistIS_M_Labels,$C33)/1000 -> 2.275 | J33: =SUMIFS(INDEX(_HistIS_M_Data,0,MATCH(J$5,_HistIS_M_MonthEnd,0)),_HistIS_M_Labels,$C33)/1000 -> 2.17995 | K33: =SUMIFS(INDEX(_HistIS_M_Data,0,MATCH(K$5,_HistIS_M_MonthEnd,0)),_HistIS_M_Labels,$C33)/1000 -> -26.07398 | L33: =SUMIFS(INDEX(_HistIS_M_Data,0,MATCH(L$5,_HistIS_M_MonthEnd,0)),_HistIS_M_Labels,$C33)/1000 -> 40.67618 | M33: =SUMIFS(INDEX(_HistIS_M_Data,0,MATCH(M$5,_HistIS_M_MonthEnd,0)),_HistIS_M_Labels,$C33)/1000 -> 0 | N33: =SUMIFS(INDEX(_HistIS_M_Data,0,MATCH(N$5,_HistIS_M_MonthEnd,0)),_HistIS_M_Labels,$C33)/1000 -> 2.9 | O33: =SUMIFS(INDEX(_HistIS_M_Data,0,MATCH(O$5,_HistIS_M_MonthEnd,0)),_HistIS_M_Labels,$C33)/1000 -> 2.83227 | ... AE33: =SUMIFS(INDEX(_HistIS_M_Data,0,MATCH(AE$5,_HistIS_M_MonthEnd,0)),_HistIS_M_Labels,$C33)/1000 -> 0
C34: Legal Fees - Fundraising | D34: $000 | E34: I/S | F34: =SUM(H34:AE34) -> 108.24385 | H34: =SUMIFS(INDEX(_HistIS_M_Data,0,MATCH(H$5,_HistIS_M_MonthEnd,0)),_HistIS_M_Labels,$C34)/1000 -> 0 | I34: =SUMIFS(INDEX(_HistIS_M_Data,0,MATCH(I$5,_HistIS_M_MonthEnd,0)),_HistIS_M_Labels,$C34)/1000 -> 0 | J34: =SUMIFS(INDEX(_HistIS_M_Data,0,MATCH(J$5,_HistIS_M_MonthEnd,0)),_HistIS_M_Labels,$C34)/1000 -> 0 | K34: =SUMIFS(INDEX(_HistIS_M_Data,0,MATCH(K$5,_HistIS_M_MonthEnd,0)),_HistIS_M_Labels,$C34)/1000 -> 0 | L34: =SUMIFS(INDEX(_HistIS_M_Data,0,MATCH(L$5,_HistIS_M_MonthEnd,0)),_HistIS_M_Labels,$C34)/1000 -> 0 | M34: =SUMIFS(INDEX(_HistIS_M_Data,0,MATCH(M$5,_HistIS_M_MonthEnd,0)),_HistIS_M_Labels,$C34)/1000 -> 0 | N34: =SUMIFS(INDEX(_HistIS_M_Data,0,MATCH(N$5,_HistIS_M_MonthEnd,0)),_HistIS_M_Labels,$C34)/1000 -> 0 | O34: =SUMIFS(INDEX(_HistIS_M_Data,0,MATCH(O$5,_HistIS_M_MonthEnd,0)),_HistIS_M_Labels,$C34)/1000 -> 0 | ... AE34: =SUMIFS(INDEX(_HistIS_M_Data,0,MATCH(AE$5,_HistIS_M_MonthEnd,0)),_HistIS_M_Labels,$C34)/1000 -> 5.122
C35: Total Legal Fees | D35: $000 | F35: =SUM(H35:AE35) -> 626.26934 | H35: =SUM(H32:H34) -> 0.37863 | I35: =SUM(I32:I34) -> 17.193 | J35: =SUM(J32:J34) -> 4.78995 | K35: =SUM(K32:K34) -> -12.99698 | L35: =SUM(L32:L34) -> 62.15268 | M35: =SUM(M32:M34) -> 6.267 | N35: =SUM(N32:N34) -> 6.17045 | O35: =SUM(O32:O34) -> 11.12927 | ... AE35: =SUM(AE32:AE34) -> 46.838
C37: Marketing | D37: $000 | E37: I/S | F37: =SUM(H37:AE37) -> 217.0986 | H37: =SUMIFS(INDEX(_HistIS_M_Data,0,MATCH(H$5,_HistIS_M_MonthEnd,0)),_HistIS_M_Labels,$C37)/1000 -> 0 | I37: =SUMIFS(INDEX(_HistIS_M_Data,0,MATCH(I$5,_HistIS_M_MonthEnd,0)),_HistIS_M_Labels,$C37)/1000 -> 3.84 | J37: =SUMIFS(INDEX(_HistIS_M_Data,0,MATCH(J$5,_HistIS_M_MonthEnd,0)),_HistIS_M_Labels,$C37)/1000 -> 0 | K37: =SUMIFS(INDEX(_HistIS_M_Data,0,MATCH(K$5,_HistIS_M_MonthEnd,0)),_HistIS_M_Labels,$C37)/1000 -> 6.13015 | L37: =SUMIFS(INDEX(_HistIS_M_Data,0,MATCH(L$5,_HistIS_M_MonthEnd,0)),_HistIS_M_Labels,$C37)/1000 -> 0.925 | M37: =SUMIFS(INDEX(_HistIS_M_Data,0,MATCH(M$5,_HistIS_M_MonthEnd,0)),_HistIS_M_Labels,$C37)/1000 -> 1.72456 | N37: =SUMIFS(INDEX(_HistIS_M_Data,0,MATCH(N$5,_HistIS_M_MonthEnd,0)),_HistIS_M_Labels,$C37)/1000 -> 3.125 | O37: =SUMIFS(INDEX(_HistIS_M_Data,0,MATCH(O$5,_HistIS_M_MonthEnd,0)),_HistIS_M_Labels,$C37)/1000 -> 3.006 | ... AE37: =SUMIFS(INDEX(_HistIS_M_Data,0,MATCH(AE$5,_HistIS_M_MonthEnd,0)),_HistIS_M_Labels,$C37)/1000 -> 14.263
C38: Government Affairs | D38: $000 | E38: I/S | F38: =SUM(H38:AE38) -> 648.28291 | H38: =SUMIFS(INDEX(_HistIS_M_Data,0,MATCH(H$5,_HistIS_M_MonthEnd,0)),_HistIS_M_Labels,$C38)/1000 -> 0 | I38: =SUMIFS(INDEX(_HistIS_M_Data,0,MATCH(I$5,_HistIS_M_MonthEnd,0)),_HistIS_M_Labels,$C38)/1000 -> 0 | J38: =SUMIFS(INDEX(_HistIS_M_Data,0,MATCH(J$5,_HistIS_M_MonthEnd,0)),_HistIS_M_Labels,$C38)/1000 -> 0 | K38: =SUMIFS(INDEX(_HistIS_M_Data,0,MATCH(K$5,_HistIS_M_MonthEnd,0)),_HistIS_M_Labels,$C38)/1000 -> 0 | L38: =SUMIFS(INDEX(_HistIS_M_Data,0,MATCH(L$5,_HistIS_M_MonthEnd,0)),_HistIS_M_Labels,$C38)/1000 -> 0 | M38: =SUMIFS(INDEX(_HistIS_M_Data,0,MATCH(M$5,_HistIS_M_MonthEnd,0)),_HistIS_M_Labels,$C38)/1000 -> 0 | N38: =SUMIFS(INDEX(_HistIS_M_Data,0,MATCH(N$5,_HistIS_M_MonthEnd,0)),_HistIS_M_Labels,$C38)/1000 -> 5 | O38: =SUMIFS(INDEX(_HistIS_M_Data,0,MATCH(O$5,_HistIS_M_MonthEnd,0)),_HistIS_M_Labels,$C38)/1000 -> 2.29166 | ... AE38: =SUMIFS(INDEX(_HistIS_M_Data,0,MATCH(AE$5,_HistIS_M_MonthEnd,0)),_HistIS_M_Labels,$C38)/1000 -> 95
C39: T&E | D39: $000 | E39: I/S | F39: =SUM(H39:AE39) -> 680.92805 | H39: =SUMIFS(INDEX(_HistIS_M_Data,0,MATCH(H$5,_HistIS_M_MonthEnd,0)),_HistIS_M_Labels,$C39)/1000 -> 16.10633 | I39: =SUMIFS(INDEX(_HistIS_M_Data,0,MATCH(I$5,_HistIS_M_MonthEnd,0)),_HistIS_M_Labels,$C39)/1000 -> 18.83156 | J39: =SUMIFS(INDEX(_HistIS_M_Data,0,MATCH(J$5,_HistIS_M_MonthEnd,0)),_HistIS_M_Labels,$C39)/1000 -> 26.82209 | K39: =SUMIFS(INDEX(_HistIS_M_Data,0,MATCH(K$5,_HistIS_M_MonthEnd,0)),_HistIS_M_Labels,$C39)/1000 -> 50.23078 | L39: =SUMIFS(INDEX(_HistIS_M_Data,0,MATCH(L$5,_HistIS_M_MonthEnd,0)),_HistIS_M_Labels,$C39)/1000 -> 18.80301 | M39: =SUMIFS(INDEX(_HistIS_M_Data,0,MATCH(M$5,_HistIS_M_MonthEnd,0)),_HistIS_M_Labels,$C39)/1000 -> 14.7223 | N39: =SUMIFS(INDEX(_HistIS_M_Data,0,MATCH(N$5,_HistIS_M_MonthEnd,0)),_HistIS_M_Labels,$C39)/1000 -> 19.04436 | O39: =SUMIFS(INDEX(_HistIS_M_Data,0,MATCH(O$5,_HistIS_M_MonthEnd,0)),_HistIS_M_Labels,$C39)/1000 -> 8.54462 | ... AE39: =SUMIFS(INDEX(_HistIS_M_Data,0,MATCH(AE$5,_HistIS_M_MonthEnd,0)),_HistIS_M_Labels,$C39)/1000 -> 151.724
